Workbook

Sheet Instructions, Assumptions
D11: COST BOM sheet
P14: <--Use Option Description under each column to descibe the particular option you are proposing; e.g. Starllink 5Tb solution
R18: RENTAL
P19: <--Use ITEM cell to describe the specific equipment you are proposing; e.g., Starllink Flat High Performance (FHP)
P20: <--Use CATEGORY drop down menu to select the category for the equipment; e.g., LEO VSAT equipment
P21: <--Use UNIT COST to enter the cost for ONE of the equipment items you are proposing
P22: <--Use QUANTITY (QTY) to enter the number of ITEMS you are adding to the assembly; e.g., enter 2 for a dual Starlink antenna maritime solution
P23: <--Use Notes/Comments/Assumptions to describe any non-standard ITEM assumptions e.g., this is a placeholder number until firm pricing is received from vendor
P59: <--Use PURCHASE MARKUP to enter your % markup to calculate sale price for an item, e.g., 40 for a 40% markup on your item; single unit pricing will show in the UNIT SALE PRICE cell
A80: PRICING sheet
M87: <--Use TERM (MONTHS) cell to enter the number of contracted months you are proposing to the customer; e.g. 36 for a 3 year contract
M88: <--Use NUMBER OF SITES cell to enter the number of customer sites with the exact configuration in the corresponding column from the COST BOM
M89: <--Use MONTHLY rate cell to enter the MONTHLY USD rate you are proposing to the customer
M90: <--Use INSTALL & DOWN PAYMENT cell to enter any upront down payment or estimated or fixed charged install

Sheet Rental (BOM)
A1: =Pricing!B1
A3: Customer -> | B3: ='Exec Summary'!C5 | D3: Column 1 | F3: Column 2 | H3: Column 3 | J3: Column 4 | L3: Column 5
C4: Option Description->
A6: Rental Items
D7: Column 1 | F7: Column 2 | H7: Column 3 | J7: Column 4 | L7: Column 5
A8: Item | B8: Category | C8: Unit Cost | D8: Qty | E8: Total Cost | F8: Qty | G8: Total Cost | H8: Qty | I8: Total Cost | J8: Qty | K8: Total Cost | L8: Qty | M8: Total Cost
A9: ASSEMBLY | P9: Notes / Comments / Assumptions
B10: - | C10: 0 | D10: 0 | E10: =SUM(C10*D10) | F10: 0 | G10: =F10*C10 | H10: 0 | I10: =SUM(H10*C10) | J10: 0 | K10: =SUM(J10*C10) | L10: 0 | M10: =SUM(L10*C10)
B11: - | C11: 0 | D11: 0 | E11: =SUM(C11*D11) | F11: 0 | G11: =F11*C11 | H11: 0 | I11: =SUM(H11*C11) | J11: 0 | K11: =SUM(J11*C11) | L11: 0 | M11: =SUM(L11*C11)
B12: - | C12: 0 | D12: 0 | E12: =SUM(C12*D12) | F12: 0 | G12: =F12*C12 | H12: 0 | I12: =SUM(H12*C12) | J12: 0 | K12: =SUM(J12*C12) | L12: 0 | M12: =SUM(L12*C12)
B13: - | C13: 0 | D13: 0 | E13: =SUM(C13*D13) | F13: 0 | G13: =F13*C13 | H13: 0 | I13: =SUM(H13*C13) | J13: 0 | K13: =SUM(J13*C13) | L13: 0 | M13: =SUM(L13*C13)
B14: - | C14: 0 | D14: 0 | E14: =SUM(C14*D14) | F14: 0 | G14: =F14*C14 | H14: 0 | I14: =SUM(H14*C14) | J14: 0 | K14: =SUM(J14*C14) | L14: 0 | M14: =SUM(L14*C14)
B15: - | C15: 0 | D15: 0 | E15: =SUM(C15*D15) | F15: 0 | G15: =F15*C15 | H15: 0 | I15: =SUM(H15*C15) | J15: 0 | K15: =SUM(J15*C15) | L15: 0 | M15: =SUM(L15*C15)
B16: - | C16: 0 | D16: 0 | E16: =SUM(C16*D16) | F16: 0 | G16: =F16*C16 | H16: 0 | I16: =SUM(H16*C16) | J16: 0 | K16: =SUM(J16*C16) | L16: 0 | M16: =SUM(L16*C16)
B17: - | C17: 0 | D17: 0 | E17: =SUM(C17*D17) | F17: 0 | G17: =F17*C17 | H17: 0 | I17: =SUM(H17*C17) | J17: 0 | K17: =SUM(J17*C17) | L17: 0 | M17: =SUM(L17*C17)
B18: - | C18: 0 | D18: 0 | E18: =SUM(C18*D18) | F18: 0 | G18: =F18*C18 | H18: 0 | I18: =SUM(H18*C18) | J18: 0 | K18: =SUM(J18*C18) | L18: 0 | M18: =SUM(L18*C18)
B19: - | C19: 0 | D19: 0 | E19: =SUM(C19*D19) | F19: 0 | G19: =F19*C19 | H19: 0 | I19: =SUM(H19*C19) | J19: 0 | K19: =SUM(J19*C19) | L19: 0 | M19: =SUM(L19*C19)
B20: - | C20: 0 | D20: 0 | E20: =SUM(C20*D20) | F20: 0 | G20: =F20*C20 | H20: 0 | I20: =SUM(H20*C20) | J20: 0 | K20: =SUM(J20*C20) | L20: 0 | M20: =SUM(L20*C20)
B21: - | C21: 0 | D21: 0 | E21: =SUM(C21*D21) | F21: 0 | G21: =F21*C21 | H21: 0 | I21: =SUM(H21*C21) | J21: 0 | K21: =SUM(J21*C21) | L21: 0 | M21: =SUM(L21*C21)
... B64: - | C64: 0 | D64: 0 | E64: =SUM(C64*D64) | F64: 0 | G64: =F64*C64 | H64: 0 | I64: =SUM(H64*C64) | J64: 0 | K64: =SUM(J64*C64) | L64: 0 | M64: =SUM(L64*C64)
A65: ANCILLARY ITEMS
B66: - | C66: 0 | D66: 0 | E66: =SUM(C66*D66) | F66: 0 | G66: =SUM(F66*C66) | H66: 0 | I66: =SUM(H66*C66) | J66: 0 | K66: =SUM(J66*C66) | L66: 0 | M66: =SUM(L66*C66)
B67: - | C67: 0 | D67: 0 | E67: =SUM(C67*D67) | F67: 0 | G67: =F67*C67 | H67: 0 | I67: =SUM(H67*C67) | J67: 0 | K67: =SUM(J67*C67) | L67: 0 | M67: =SUM(L67*C67)
B68: - | C68: 0 | D68: 0 | E68: =SUM(C68*D68) | F68: 0 | G68: =F68*C68 | H68: 0 | I68: =SUM(H68*C68) | J68: 0 | K68: =SUM(J68*C68) | L68: 0 | M68: =SUM(L68*C68)
B69: - | C69: 0 | D69: 0 | E69: =SUM(C69*D69) | F69: 0 | G69: =F69*C69 | H69: 0 | I69: =SUM(H69*C69) | J69: 0 | K69: =SUM(J69*C69) | L69: 0 | M69: =SUM(L69*C69)
B70: - | C70: 0 | D70: 0 | E70: =SUM(C70*D70) | F70: 0 | G70: =F70*C70 | H70: 0 | I70: =SUM(H70*C70) | J70: 0 | K70: =SUM(J70*C70) | L70: 0 | M70: =SUM(L70*C70)
B71: - | C71: 0 | D71: 0 | E71: =SUM(C71*D71) | F71: 0 | G71: =F71*C71 | H71: 0 | I71: =SUM(H71*C71) | J71: 0 | K71: =SUM(J71*C71) | L71: 0 | M71: =SUM(L71*C71)
B72: - | C72: 0 | D72: 0 | E72: =SUM(C72*D72) | F72: 0 | G72: =F72*C72 | H72: 0 | I72: =SUM(H72*C72) | J72: 0 | K72: =SUM(J72*C72) | L72: 0 | M72: =SUM(L72*C72)
B73: - | C73: 0 | D73: 0 | E73: =SUM(C73*D73) | F73: 0 | G73: =F73*C73 | H73: 0 | I73: =SUM(H73*C73) | J73: 0 | K73: =SUM(J73*C73) | L73: 0 | M73: =SUM(L73*C73)
B74: - | C74: 0 | D74: 0 | E74: =SUM(C74*D74) | F74: 0 | G74: =F74*C74 | H74: 0 | I74: =SUM(H74*C74) | J74: 0 | K74: =SUM(J74*C74) | L74: 0 | M74: =SUM(L74*C74)
B75: - | C75: 0 | D75: 0 | E75: =SUM(C75*D75) | F75: 0 | G75: =F75*C75 | H75: 0 | I75: =SUM(H75*C75) | J75: 0 | K75: =SUM(J75*C75) | L75: 0 | M75: =SUM(L75*C75)
B76: - | C76: 0 | D76: 0 | E76: =SUM(C76*D76) | F76: 0 | G76: =F76*C76 | H76: 0 | I76: =SUM(H76*C76) | J76: 0 | K76: =SUM(J76*C76) | L76: 0 | M76: =SUM(L76*C76)
B77: - | C77: 0 | D77: 0 | E77: =SUM(C77*D77) | F77: 0 | G77: =F77*C77 | H77: 0 | I77: =SUM(H77*C77) | J77: 0 | K77: =SUM(J77*C77) | L77: 0 | M77: =SUM(L77*C77)
B78: - | C78: 0 | D78: 0 | E78: =SUM(C78*D78) | F78: 0 | G78: =F78*C78 | H78: 0 | I78: =SUM(H78*C78) | J78: 0 | K78: =SUM(J78*C78) | L78: 0 | M78: =SUM(L78*C78)
... B103: - | C103: 0 | D103: 0 | E103: =SUM(C103*D103) | F103: 0 | G103: =F103*C103 | H103: 0 | I103: =SUM(H103*C103) | J103: 0 | K103: =SUM(J103*C103) | L103: 0 | M103: =SUM(L103*C103)
B104: - | C104: 0 | D104: 0 | E104: =SUM(C104*D104) | F104: 0 | G104: =SUM(F104*C104) | H104: 0 | I104: =SUM(H104*C104) | J104: 0 | K104: =SUM(J104*C104) | L104: 0 | M104: =SUM(L104*C104)
A105: INSTALLATION
B106: - | C106: 0 | D106: 0 | E106: =SUM(C106*D106) | F106: 0 | G106: =SUM(F106*C106) | H106: 0 | I106: =SUM(H106*C106) | J106: 0 | K106: =SUM(J106*C106) | L106: 0 | M106: =SUM(L106*C106)
B107: - | C107: 0 | D107: 0 | E107: =SUM(C107*D107) | F107: 0 | G107: =F107*C107 | H107: 0 | I107: =SUM(H107*C107) | J107: 0 | K107: =SUM(J107*C107) | L107: 0 | M107: =SUM(L107*C107)
B108: - | C108: 0 | D108: 0 | E108: =SUM(C108*D108) | F108: 0 | G108: =F108*C108 | H108: 0 | I108: =SUM(H108*C108) | J108: 0 | K108: =SUM(J108*C108) | L108: 0 | M108: =SUM(L108*C108)
...

Sheet Sale (BOM)
A1: =Pricing!B1
A3: Customer -> | B3: ='Exec Summary'!C5
A5: Sale Items
F6: Column 1 | I6: Column 2 | L6: Column 3 | O6: Column 4 | R6: Column 5
E7: Description-->
A8: Item | B8: Category | C8: Unit Cost | D8: Target Margin | E8: Unit Sales Price | F8: Qty | G8: Total Cost | H8: Total Sale Price | I8: Qty | J8: Total Cost | K8: Total Sale Price | L8: Qty | M8: Total Cost | N8: Total Sale Price | O8: Qty | P8: Total Cost | Q8: Total Sale Price | R8: Qty | S8: Total Cost | T8: Total Sale Price
A9: ASSEMBLY | W9: Notes / Comments / Assumptions
B10: - | C10: 0 | D10: 0 | E10: =IFERROR(C10/(1-D10),0) | F10: 0 | G10: =SUM(C10*F10) | H10: =SUM(E10*F10) | I10: 0 | J10: =SUM(I10*C10) | K10: =SUM(E10*I10) | L10: 0 | M10: =SUM(L10*C10) | N10: =SUM(E10*L10) | O10: 0 | P10: =SUM(O10*C10) | Q10: =SUM(E10*O10) | R10: 0 | S10: =SUM(R10*C10) | T10: =SUM(E10*R10)
B11: - | C11: 0 | D11: 0 | E11: =IFERROR(C11/(1-D11),0) | F11: 0 | G11: =SUM(C11*F11) | H11: =SUM(E11*F11) | I11: 0 | J11: =SUM(I11*C11) | K11: =SUM(E11*I11) | L11: 0 | M11: =SUM(L11*C11) | N11: =SUM(E11*L11) | O11: 0 | P11: =SUM(O11*C11) | Q11: =SUM(E11*O11) | R11: 0 | S11: =SUM(R11*C11) | T11: =SUM(E11*R11)
B12: - | C12: 0 | D12: 0 | E12: =IFERROR(C12/(1-D12),0) | F12: 0 | G12: =SUM(C12*F12) | H12: =SUM(E12*F12) | I12: 0 | J12: =SUM(I12*C12) | K12: =SUM(E12*I12) | L12: 0 | M12: =SUM(L12*C12) | N12: =SUM(E12*L12) | O12: 0 | P12: =SUM(O12*C12) | Q12: =SUM(E12*O12) | R12: 0 | S12: =SUM(R12*C12) | T12: =SUM(E12*R12)
B13: - | C13: 0 | D13: 0 | E13: =IFERROR(C13/(1-D13),0) | F13: 0 | G13: =SUM(C13*F13) | H13: =SUM(E13*F13) | I13: 0 | J13: =SUM(I13*C13) | K13: =SUM(E13*I13) | L13: 0 | M13: =SUM(L13*C13) | N13: =SUM(E13*L13) | O13: 0 | P13: =SUM(O13*C13) | Q13: =SUM(E13*O13) | R13: 0 | S13: =SUM(R13*C13) | T13: =SUM(E13*R13)
B14: - | C14: 0 | D14: 0 | E14: =IFERROR(C14/(1-D14),0) | F14: 0 | G14: =SUM(C14*F14) | H14: =SUM(E14*F14) | I14: 0 | J14: =SUM(I14*C14) | K14: =SUM(E14*I14) | L14: 0 | M14: =SUM(L14*C14) | N14: =SUM(E14*L14) | O14: 0 | P14: =SUM(O14*C14) | Q14: =SUM(E14*O14) | R14: 0 | S14: =SUM(R14*C14) | T14: =SUM(E14*R14)
B15: - | C15: 0 | D15: 0 | E15: =IFERROR(C15/(1-D15),0) | F15: 0 | G15: =SUM(C15*F15) | H15: =SUM(E15*F15) | I15: 0 | J15: =SUM(I15*C15) | K15: =SUM(E15*I15) | L15: 0 | M15: =SUM(L15*C15) | N15: =SUM(E15*L15) | O15: 0 | P15: =SUM(O15*C15) | Q15: =SUM(E15*O15) | R15: 0 | S15: =SUM(R15*C15) | T15: =SUM(E15*R15)
B16: - | C16: 0 | D16: 0 | E16: =IFERROR(C16/(1-D16),0) | F16: 0 | G16: =SUM(C16*F16) | H16: =SUM(E16*F16) | I16: 0 | J16: =SUM(I16*C16) | K16: =SUM(E16*I16) | L16: 0 | M16: =SUM(L16*C16) | N16: =SUM(E16*L16) | O16: 0 | P16: =SUM(O16*C16) | Q16: =SUM(E16*O16) | R16: 0 | S16: =SUM(R16*C16) | T16: =SUM(E16*R16)
B17: - | C17: 0 | D17: 0 | E17: =IFERROR(C17/(1-D17),0) | F17: 0 | G17: =SUM(C17*F17) | H17: =SUM(E17*F17) | I17: 0 | J17: =SUM(I17*C17) | K17: =SUM(E17*I17) | L17: 0 | M17: =SUM(L17*C17) | N17: =SUM(E17*L17) | O17: 0 | P17: =SUM(O17*C17) | Q17: =SUM(E17*O17) | R17: 0 | S17: =SUM(R17*C17) | T17: =SUM(E17*R17)
B18: - | C18: 0 | D18: 0 | E18: =IFERROR(C18/(1-D18),0) | F18: 0 | G18: =SUM(C18*F18) | H18: =SUM(E18*F18) | I18: 0 | J18: =SUM(I18*C18) | K18: =SUM(E18*I18) | L18: 0 | M18: =SUM(L18*C18) | N18: =SUM(E18*L18) | O18: 0 | P18: =SUM(O18*C18) | Q18: =SUM(E18*O18) | R18: 0 | S18: =SUM(R18*C18) | T18: =SUM(E18*R18)
B19: - | C19: 0 | D19: 0 | E19: =IFERROR(C19/(1-D19),0) | F19: 0 | G19: =SUM(C19*F19) | H19: =SUM(E19*F19) | I19: 0 | J19: =SUM(I19*C19) | K19: =SUM(E19*I19) | L19: 0 | M19: =SUM(L19*C19) | N19: =SUM(E19*L19) | O19: 0 | P19: =SUM(O19*C19) | Q19: =SUM(E19*O19) | R19: 0 | S19: =SUM(R19*C19) | T19: =SUM(E19*R19)
B20: - | C20: 0 | D20: 0 | E20: =IFERROR(C20/(1-D20),0) | F20: 0 | G20: =SUM(C20*F20) | H20: =SUM(E20*F20) | I20: 0 | J20: =SUM(I20*C20) | K20: =SUM(E20*I20) | L20: 0 | M20: =SUM(L20*C20) | N20: =SUM(E20*L20) | O20: 0 | P20: =SUM(O20*C20) | Q20: =SUM(E20*O20) | R20: 0 | S20: =SUM(R20*C20) | T20: =SUM(E20*R20)
B21: - | C21: 0 | D21: 0 | E21: =IFERROR(C21/(1-D21),0) | F21: 0 | G21: =SUM(C21*F21) | H21: =SUM(E21*F21) | I21: 0 | J21: =SUM(I21*C21) | K21: =SUM(E21*I21) | L21: 0 | M21: =SUM(L21*C21) | N21: =SUM(E21*L21) | O21: 0 | P21: =SUM(O21*C21) | Q21: =SUM(E21*O21) | R21: 0 | S21: =SUM(R21*C21) | T21: =SUM(E21*R21)
... B28: - | C28: 0 | D28: 0 | E28: =IFERROR(C28/(1-D28),0) | F28: 0 | G28: =SUM(C28*F28) | H28: =SUM(E28*F28) | I28: 0 | J28: =SUM(I28*C28) | K28: =SUM(E28*I28) | L28: 0 | M28: =SUM(L28*C28) | N28: =SUM(E28*L28) | O28: 0 | P28: =SUM(O28*C28) | Q28: =SUM(E28*O28) | R28: 0 | S28: =SUM(R28*C28) | T28: =SUM(E28*R28)
A29: ANCILLARY ITEMS
B30: - | C30: 0 | D30: 0 | E30: =IFERROR(C30/(1-D30),0) | F30: 0 | G30: =SUM(C30*F30) | H30: =SUM(E30*F30) | I30: 0 | J30: =SUM(I30*C30) | K30: =SUM(E30*I30) | L30: 0 | M30: =SUM(L30*C30) | N30: =SUM(E30*L30) | O30: 0 | P30: =SUM(O30*C30) | Q30: =SUM(E30*O30) | R30: 0 | S30: =SUM(R30*C30) | T30: =SUM(E30*R30)
B31: - | C31: 0 | D31: 0 | E31: =IFERROR(C31/(1-D31),0) | F31: 0 | G31: =SUM(C31*F31) | H31: =SUM(E31*F31) | I31: 0 | J31: =SUM(I31*C31) | K31: =SUM(E31*I31) | L31: 0 | M31: =SUM(L31*C31) | N31: =SUM(E31*L31) | O31: 0 | P31: =SUM(O31*C31) | Q31: =SUM(E31*O31) | R31: 0 | S31: =SUM(R31*C31) | T31: =SUM(E31*R31)
B32: - | C32: 0 | D32: 0 | E32: =IFERROR(C32/(1-D32),0) | F32: 0 | G32: =SUM(C32*F32) | H32: =SUM(E32*F32) | I32: 0 | J32: =SUM(I32*C32) | K32: =SUM(E32*I32) | L32: 0 | M32: =SUM(L32*C32) | N32: =SUM(E32*L32) | O32: 0 | P32: =SUM(O32*C32) | Q32: =SUM(E32*O32) | R32: 0 | S32: =SUM(R32*C32) | T32: =SUM(E32*R32)
B33: - | C33: 0 | D33: 0 | E33: =IFERROR(C33/(1-D33),0) | F33: 0 | G33: =SUM(C33*F33) | H33: =SUM(E33*F33) | I33: 0 | J33: =SUM(I33*C33) | K33: =SUM(E33*I33) | L33: 0 | M33: =SUM(L33*C33) | N33: =SUM(E33*L33) | O33: 0 | P33: =SUM(O33*C33) | Q33: =SUM(E33*O33) | R33: 0 | S33: =SUM(R33*C33) | T33: =SUM(E33*R33)
B34: - | C34: 0 | D34: 0 | E34: =IFERROR(C34/(1-D34),0) | F34: 0 | G34: =SUM(C34*F34) | H34: =SUM(E34*F34) | I34: 0 | J34: =SUM(I34*C34) | K34: =SUM(E34*I34) | L34: 0 | M34: =SUM(L34*C34) | N34: =SUM(E34*L34) | O34: 0 | P34: =SUM(O34*C34) | Q34: =SUM(E34*O34) | R34: 0 | S34: =SUM(R34*C34) | T34: =SUM(E34*R34)
B35: - | C35: 0 | D35: 0 | E35: =IFERROR(C35/(1-D35),0) | F35: 0 | G35: =SUM(C35*F35) | H35: =SUM(E35*F35) | I35: 0 | J35: =SUM(I35*C35) | K35: =SUM(E35*I35) | L35: 0 | M35: =SUM(L35*C35) | N35: =SUM(E35*L35) | O35: 0 | P35: =SUM(O35*C35) | Q35: =SUM(E35*O35) | R35: 0 | S35: =SUM(R35*C35) | T35: =SUM(E35*R35)
B36: - | C36: 0 | D36: 0 | E36: =IFERROR(C36/(1-D36),0) | F36: 0 | G36: =SUM(C36*F36) | H36: =SUM(E36*F36) | I36: 0 | J36: =SUM(I36*C36) | K36: =SUM(E36*I36) | L36: 0 | M36: =SUM(L36*C36) | N36: =SUM(E36*L36) | O36: 0 | P36: =SUM(O36*C36) | Q36: =SUM(E36*O36) | R36: 0 | S36: =SUM(R36*C36) | T36: =SUM(E36*R36)
B37: - | C37: 0 | D37: 0 | E37: =IFERROR(C37/(1-D37),0) | F37: 0 | G37: =SUM(C37*F37) | H37: =SUM(E37*F37) | I37: 0 | J37: =SUM(I37*C37) | K37: =SUM(E37*I37) | L37: 0 | M37: =SUM(L37*C37) | N37: =SUM(E37*L37) | O37: 0 | P37: =SUM(O37*C37) | Q37: =SUM(E37*O37) | R37: 0 | S37: =SUM(R37*C37) | T37: =SUM(E37*R37)
B38: - | C38: 0 | D38: 0 | E38: =IFERROR(C38/(1-D38),0) | F38: 0 | G38: =SUM(C38*F38) | H38: =SUM(E38*F38) | I38: 0 | J38: =SUM(I38*C38) | K38: =SUM(E38*I38) | L38: 0 | M38: =SUM(L38*C38) | N38: =SUM(E38*L38) | O38: 0 | P38: =SUM(O38*C38) | Q38: =SUM(E38*O38) | R38: 0 | S38: =SUM(R38*C38) | T38: =SUM(E38*R38)
B39: - | C39: 0 | D39: 0 | E39: =IFERROR(C39/(1-D39),0) | F39: 0 | G39: =SUM(C39*F39) | H39: =SUM(E39*F39) | I39: 0 | J39: =SUM(I39*C39) | K39: =SUM(E39*I39) | L39: 0 | M39: =SUM(L39*C39) | N39: =SUM(E39*L39) | O39: 0 | P39: =SUM(O39*C39) | Q39: =SUM(E39*O39) | R39: 0 | S39: =SUM(R39*C39) | T39: =SUM(E39*R39)
B40: - | C40: 0 | D40: 0 | E40: =IFERROR(C40/(1-D40),0) | F40: 0 | G40: =SUM(C40*F40) | H40: =SUM(E40*F40) | I40: 0 | J40: =SUM(I40*C40) | K40: =SUM(E40*I40) | L40: 0 | M40: =SUM(L40*C40) | N40: =SUM(E40*L40) | O40: 0 | P40: =SUM(O40*C40) | Q40: =SUM(E40*O40) | R40: 0 | S40: =SUM(R40*C40) | T40: =SUM(E40*R40)
B41: - | C41: 0 | D41: 0 | E41: =IFERROR(C41/(1-D41),0) | F41: 0 | G41: =SUM(C41*F41) | H41: =SUM(E41*F41) | I41: 0 | J41: =SUM(I41*C41) | K41: =SUM(E41*I41) | L41: 0 | M41: =SUM(L41*C41) | N41: =SUM(E41*L41) | O41: 0 | P41: =SUM(O41*C41) | Q41: =SUM(E41*O41) | R41: 0 | S41: =SUM(R41*C41) | T41: =SUM(E41*R41)
A42: INSTALLATION
B43: - | C43: 0 | D43: 0 | E43: =IFERROR(C43/(1-D43),0) | F43: 0 | G43: =SUM(C43*F43) | H43: =SUM(E43*F43) | I43: 0 | J43: =SUM(I43*C43) | K43: =SUM(E43*I43) | L43: 0 | M43: =SUM(L43*C43) | N43: =SUM(E43*L43) | O43: 0 | P43: =SUM(O43*C43) | Q43: =SUM(E43*O43) | R43: 0 | S43: =SUM(R43*C43) | T43: =SUM(E43*R43)
B44: - | C44: 0 | D44: 0 | E44: =IFERROR(C44/(1-D44),0) | F44: 0 | G44: =SUM(C44*F44) | H44: =SUM(E44*F44) | I44: 0 | J44: =SUM(I44*C44) | K44: =SUM(E44*I44) | L44: 0 | M44: =SUM(L44*C44) | N44: =SUM(E44*L44) | O44: 0 | P44: =SUM(O44*C44) | Q44: =SUM(E44*O44) | R44: 0 | S44: =SUM(R44*C44) | T44: =SUM(E44*R44)
B45: - | C45: 0 | D45: 0 | E45: =IFERROR(C45/(1-D45),0) | F45: 0 | G45: =SUM(C45*F45) | H45: =SUM(E45*F45) | I45: 0 | J45: =SUM(I45*C45) | K45: =SUM(E45*I45) | L45: 0 | M45: =SUM(L45*C45) | N45: =SUM(E45*L45) | O45: 0 | P45: =SUM(O45*C45) | Q45: =SUM(E45*O45) | R45: 0 | S45: =SUM(R45*C45) | T45: =SUM(E45*R45)
B46: - | C46: 0 | D46: 0 | E46: =IFERROR(C46/(1-D46),0) | F46: 0 | G46: =SUM(C46*F46) | H46: =SUM(E46*F46) | I46: 0 | J46: =SUM(I46*C46) | K46: =SUM(E46*I46) | L46: 0 | M46: =SUM(L46*C46) | N46: =SUM(E46*L46) | O46: 0 | P46: =SUM(O46*C46) | Q46: =SUM(E46*O46) | R46: 0 | S46: =SUM(R46*C46) | T46: =SUM(E46*R46)
B47: - | C47: 0 | D47: 0 | E47: =IFERROR(C47/(1-D47),0) | F47: 0 | G47: =SUM(C47*F47) | H47: =SUM(E47*F47) | I47: 0 | J47: =SUM(I47*C47) | K47: =SUM(E47*I47) | L47: 0 | M47: =SUM(L47*C47) | N47: =SUM(E47*L47) | O47: 0 | P47: =SUM(O47*C47) | Q47: =SUM(E47*O47) | R47: 0 | S47: =SUM(R47*C47) | T47: =SUM(E47*R47)
B48: - | C48: 0 | D48: 0 | E48: =IFERROR(C48/(1-D48),0) | F48: 0 | G48: =SUM(C48*F48) | H48: =SUM(E48*F48) | I48: 0 | J48: =SUM(I48*C48) | K48: =SUM(E48*I48) | L48: 0 | M48: =SUM(L48*C48) | N48: =SUM(E48*L48) | O48: 0 | P48: =SUM(O48*C48) | Q48: =SUM(E48*O48) | R48: 0 | S48: =SUM(R48*C48) | T48: =SUM(E48*R48)
...

Sheet Pricing
B1: Satellite: P = Version 2026-08-28
B2: Rental/Lease Site(s) Options | E2: 1 | F2: 2 | G2: 3 | H2: 4 | I2: 5 | L2: Notes / Comments / Assumptions
B3: Option Description | D3: → | E3: ='Rental (BOM)'!D4 | F3: ='Rental (BOM)'!F4 | G3: ='Rental (BOM)'!H4 | H3: ='Rental (BOM)'!J4 | I3: ='Rental (BOM)'!L4
B4: Term (Months) | D4: → | E4: 0 | F4: 0 | G4: 0 | H4: 0 | I4: 0
B5: Number of Sites (Same Configuration) | D5: → | E5: 0 | F5: 0 | G5: 0 | H5: 0 | I5: 0
B6: Monthly Rate per site | D6: → | E6: 0 | F6: 0 | G6: 0 | H6: 0 | I6: 0
B7: Flat Rate Installation or Down Payment | D7: → | E7: 0 | F7: 0 | G7: 0 | H7: 0 | I7: 0
B10: Rental/Lease Items | D10: Summary | E10: 1 | F10: 2 | G10: 3 | H10: 4 | I10: 5
B11: Materials Cost | D11: =SUM(D12:D22) | E11: =SUM(E12:E22) | F11: =SUM(F12:F22) | G11: =SUM(G12:G22) | H11: =SUM(H12:H22) | I11: =SUM(I12:I22)
B12: Install Equipment | D12: =SUM(E12,F12,G12,H12,I12) | E12: =SUMIF('Rental (BOM)'!$B$10:$B$104,Pricing!B12,'Rental (BOM)'!$E$10:$E$104)*$E$5 | F12: =SUMIF('Rental (BOM)'!$B$10:$B$104,Pricing!B12,'Rental (BOM)'!$G$10:$G$104)*$F$5 | G12: =SUMIF('Rental (BOM)'!$B$10:$B$104,Pricing!B12,'Rental (BOM)'!$I$10:$I$104)*$G$5 | H12: =SUMIF('Rental (BOM)'!$B$10:$B$104,Pricing!B12,'Rental (BOM)'!$K$10:$M$104)*$H$5 | I12: =SUMIF('Rental (BOM)'!$B$10:$B$104,Pricing!B12,'Rental (BOM)'!$M$10:$M$104)*$I$5
B13: Install Misc Goods | D13: =SUM(E13,F13,G13,H13,I13) | E13: =SUMIF('Rental (BOM)'!$B$10:$B$104,Pricing!B13,'Rental (BOM)'!$E$10:$E$104)*$E$5 | F13: =SUMIF('Rental (BOM)'!$B$10:$B$104,Pricing!B13,'Rental (BOM)'!$G$10:$G$104)*$F$5 | G13: =SUMIF('Rental (BOM)'!$B$10:$B$104,Pricing!B13,'Rental (BOM)'!$I$10:$I$104)*$G$5 | H13: =SUMIF('Rental (BOM)'!$B$10:$B$104,Pricing!B13,'Rental (BOM)'!$K$10:$M$104)*$H$5 | I13: =SUMIF('Rental (BOM)'!$B$10:$B$104,Pricing!B13,'Rental (BOM)'!$M$10:$M$104)*$I$5
B14: RF Equipment | D14: =SUM(E14,F14,G14,H14,I14) | E14: =SUMIF('Rental (BOM)'!$B$10:$B$104,Pricing!B14,'Rental (BOM)'!$E$10:$E$104)*$E$5 | F14: =SUMIF('Rental (BOM)'!$B$10:$B$104,Pricing!B14,'Rental (BOM)'!$G$10:$G$104)*$F$5 | G14: =SUMIF('Rental (BOM)'!$B$10:$B$104,Pricing!B14,'Rental (BOM)'!$I$10:$I$104)*$G$5 | H14: =SUMIF('Rental (BOM)'!$B$10:$B$104,Pricing!B14,'Rental (BOM)'!$K$10:$M$104)*$H$5 | I14: =SUMIF('Rental (BOM)'!$B$10:$B$104,Pricing!B14,'Rental (BOM)'!$M$10:$M$104)*$I$5
B15: LEO VSAT Equipment | D15: =SUM(E15,F15,G15,H15,I15) | E15: =SUMIF('Rental (BOM)'!$B$10:$B$104,Pricing!B15,'Rental (BOM)'!$E$10:$E$104)*$E$5 | F15: =SUMIF('Rental (BOM)'!$B$10:$B$104,Pricing!B15,'Rental (BOM)'!$G$10:$G$104)*$F$5 | G15: =SUMIF('Rental (BOM)'!$B$10:$B$104,Pricing!B15,'Rental (BOM)'!$I$10:$I$104)*$G$5 | H15: =SUMIF('Rental (BOM)'!$B$10:$B$104,Pricing!B15,'Rental (BOM)'!$K$10:$M$104)*$H$5 | I15: =SUMIF('Rental (BOM)'!$B$10:$B$104,Pricing!B15,'Rental (BOM)'!$M$10:$M$104)*$I$5
B16: MEO VSAT Equipment | D16: =SUM(E16,F16,G16,H16,I16) | E16: =SUMIF('Rental (BOM)'!$B$10:$B$104,Pricing!B16,'Rental (BOM)'!$E$10:$E$104)*$E$5 | F16: =SUMIF('Rental (BOM)'!$B$10:$B$104,Pricing!B16,'Rental (BOM)'!$G$10:$G$104)*$F$5 | G16: =SUMIF('Rental (BOM)'!$B$10:$B$104,Pricing!B16,'Rental (BOM)'!$I$10:$I$104)*$G$5 | H16: =SUMIF('Rental (BOM)'!$B$10:$B$104,Pricing!B16,'Rental (BOM)'!$K$10:$M$104)*$H$5 | I16: =SUMIF('Rental (BOM)'!$B$10:$B$104,Pricing!B16,'Rental (BOM)'!$M$10:$M$104)*$I$5
B17: GEO VSAT Equipment | D17: =SUM(E17,F17,G17,H17,I17) | E17: =SUMIF('Rental (BOM)'!$B$10:$B$104,Pricing!B17,'Rental (BOM)'!$E$10:$E$104)*$E$5 | F17: =SUMIF('Rental (BOM)'!$B$10:$B$104,Pricing!B17,'Rental (BOM)'!$G$10:$G$104)*$F$5 | G17: =SUMIF('Rental (BOM)'!$B$10:$B$104,Pricing!B17,'Rental (BOM)'!$I$10:$I$104)*$G$5 | H17: =SUMIF('Rental (BOM)'!$B$10:$B$104,Pricing!B17,'Rental (BOM)'!$K$10:$M$104)*$H$5 | I17: =SUMIF('Rental (BOM)'!$B$10:$B$104,Pricing!B17,'Rental (BOM)'!$M$10:$M$104)*$I$5
B18: VSAT - GENERAL EQUIP (Modems, OBM, etc.) | D18: =SUM(E18,F18,G18,H18,I18) | E18: =SUMIF('Rental (BOM)'!$B$10:$B$104,Pricing!B18,'Rental (BOM)'!$E$10:$E$104)*$E$5 | F18: =SUMIF('Rental (BOM)'!$B$10:$B$104,Pricing!B18,'Rental (BOM)'!$G$10:$G$104)*$F$5 | G18: =SUMIF('Rental (BOM)'!$B$10:$B$104,Pricing!B18,'Rental (BOM)'!$I$10:$I$104)*$G$5 | H18: =SUMIF('Rental (BOM)'!$B$10:$B$104,Pricing!B18,'Rental (BOM)'!$K$10:$M$104)*$H$5 | I18: =SUMIF('Rental (BOM)'!$B$10:$B$104,Pricing!B18,'Rental (BOM)'!$M$10:$M$104)*$I$5
B19: Network Equipment | D19: =SUM(E19,F19,G19,H19,I19) | E19: =SUMIF('Rental (BOM)'!$B$10:$B$104,Pricing!B19,'Rental (BOM)'!$E$10:$E$104)*$E$5 | F19: =SUMIF('Rental (BOM)'!$B$10:$B$104,Pricing!B19,'Rental (BOM)'!$G$10:$G$104)*$F$5 | G19: =SUMIF('Rental (BOM)'!$B$10:$B$104,Pricing!B19,'Rental (BOM)'!$I$10:$I$104)*$G$5 | H19: =SUMIF('Rental (BOM)'!$B$10:$B$104,Pricing!B19,'Rental (BOM)'!$K$10:$M$104)*$H$5 | I19: =SUMIF('Rental (BOM)'!$B$10:$B$104,Pricing!B19,'Rental (BOM)'!$M$10:$M$104)*$I$5
B20: Phones & Intercoms | D20: =SUM(E20,F20,G20,H20,I20) | E20: =SUMIF('Rental (BOM)'!$B$10:$B$104,Pricing!B20,'Rental (BOM)'!$E$10:$E$104)*$E$5 | F20: =SUMIF('Rental (BOM)'!$B$10:$B$104,Pricing!B20,'Rental (BOM)'!$G$10:$G$104)*$F$5 | G20: =SUMIF('Rental (BOM)'!$B$10:$B$104,Pricing!B20,'Rental (BOM)'!$I$10:$I$104)*$G$5 | H20: =SUMIF('Rental (BOM)'!$B$10:$B$104,Pricing!B20,'Rental (BOM)'!$K$10:$M$104)*$H$5 | I20: =SUMIF('Rental (BOM)'!$B$10:$B$104,Pricing!B20,'Rental (BOM)'!$M$10:$M$104)*$I$5
B21: SCADA Equipment | D21: =SUM(E21,F21,G21,H21,I21) | E21: =SUMIF('Rental (BOM)'!$B$10:$B$104,Pricing!B21,'Rental (BOM)'!$E$10:$E$104)*$E$5 | F21: =SUMIF('Rental (BOM)'!$B$10:$B$104,Pricing!B21,'Rental (BOM)'!$G$10:$G$104)*$F$5 | G21: =SUMIF('Rental (BOM)'!$B$10:$B$104,Pricing!B21,'Rental (BOM)'!$I$10:$I$104)*$G$5 | H21: =SUMIF('Rental (BOM)'!$B$10:$B$104,Pricing!B21,'Rental (BOM)'!$K$10:$M$104)*$H$5 | I21: =SUMIF('Rental (BOM)'!$B$10:$B$104,Pricing!B21,'Rental (BOM)'!$M$10:$M$104)*$I$5
B22: Other | D22: =SUM(E22,F22,G22,H22,I22) | E22: =SUMIF('Rental (BOM)'!$B$10:$B$104,Pricing!B22,'Rental (BOM)'!$E$10:$E$104)*$E$5 | F22: =SUMIF('Rental (BOM)'!$B$10:$B$104,Pricing!B22,'Rental (BOM)'!$G$10:$G$104)*$F$5 | G22: =SUMIF('Rental (BOM)'!$B$10:$B$104,Pricing!B22,'Rental (BOM)'!$I$10:$I$104)*$G$5 | H22: =SUMIF('Rental (BOM)'!$B$10:$B$104,Pricing!B22,'Rental (BOM)'!$K$10:$M$104)*$H$5 | I22: =SUMIF('Rental (BOM)'!$B$10:$B$104,Pricing!B22,'Rental (BOM)'!$M$10:$M$104)*$I$5
B23: -
B24: Labor Cost | D24: =SUM(D25:D36) | E24: =SUM(E25:E36) | F24: =SUM(F25:F36) | G24: =SUM(G25:G36) | H24: =SUM(H25:H36) | I24: =SUM(I25:I36)
B25: Project Management | D25: =SUM(E25,F25,G25,H25,I25) | E25: =SUMIF('Rental (BOM)'!$B$106:$B$126,Pricing!B25,'Rental (BOM)'!$E$106:$E$126)*$E$5 | F25: =SUMIF('Rental (BOM)'!$B$106:$B$126,Pricing!B25,'Rental (BOM)'!$G$106:$G$126)*$F$5 | G25: =SUMIF('Rental (BOM)'!$B$106:$B$126,Pricing!B25,'Rental (BOM)'!$I$106:$I$126)*$G$5 | H25: =SUMIF('Rental (BOM)'!$B$106:$B$126,Pricing!B25,'Rental (BOM)'!$K$106:$K$126)*$H$5 | I25: =SUMIF('Rental (BOM)'!$B$106:$B$126,Pricing!B25,'Rental (BOM)'!$M$106:$M$126)*$I$5
B26: Engineering | D26: =SUM(E26,F26,G26,H26,I26) | E26: =SUMIF('Rental (BOM)'!$B$106:$B$126,Pricing!B26,'Rental (BOM)'!$E$106:$E$126)*$E$5 | F26: =SUMIF('Rental (BOM)'!$B$106:$B$126,Pricing!B26,'Rental (BOM)'!$G$106:$G$126)*$F$5 | G26: =SUMIF('Rental (BOM)'!$B$106:$B$126,Pricing!B26,'Rental (BOM)'!$I$106:$I$126)*$G$5 | H26: =SUMIF('Rental (BOM)'!$B$106:$B$126,Pricing!B26,'Rental (BOM)'!$K$106:$K$126)*$H$5 | I26: =SUMIF('Rental (BOM)'!$B$106:$B$126,Pricing!B26,'Rental (BOM)'!$M$106:$M$126)*$I$5
B27: Field Installation | D27: =SUM(E27,F27,G27,H27,I27) | E27: =SUMIF('Rental (BOM)'!$B$106:$B$126,Pricing!B27,'Rental (BOM)'!$E$106:$E$126)*$E$5 | F27: =SUMIF('Rental (BOM)'!$B$106:$B$126,Pricing!B27,'Rental (BOM)'!$G$106:$G$126)*$F$5 | G27: =SUMIF('Rental (BOM)'!$B$106:$B$126,Pricing!B27,'Rental (BOM)'!$I$106:$I$126)*$G$5 | H27: =SUMIF('Rental (BOM)'!$B$106:$B$126,Pricing!B27,'Rental (BOM)'!$K$106:$K$126)*$H$5 | I27: =SUMIF('Rental (BOM)'!$B$106:$B$126,Pricing!B27,'Rental (BOM)'!$M$106:$M$126)*$I$5
B28: Labor - Admin | D28: =SUM(E28,F28,G28,H28,I28) | E28: =SUMIF('Rental (BOM)'!$B$106:$B$126,Pricing!B28,'Rental (BOM)'!$E$106:$E$126)*$E$5 | F28: =SUMIF('Rental (BOM)'!$B$106:$B$126,Pricing!B28,'Rental (BOM)'!$G$106:$G$126)*$F$5 | G28: =SUMIF('Rental (BOM)'!$B$106:$B$126,Pricing!B28,'Rental (BOM)'!$I$106:$I$126)*$G$5 | H28: =SUMIF('Rental (BOM)'!$B$106:$B$126,Pricing!B28,'Rental (BOM)'!$K$106:$K$126)*$H$5 | I28: =SUMIF('Rental (BOM)'!$B$106:$B$126,Pricing!B28,'Rental (BOM)'!$M$106:$M$126)*$I$5
B29: Labor - Documentation | D29: =SUM(E29,F29,G29,H29,I29) | E29: =SUMIF('Rental (BOM)'!$B$106:$B$126,Pricing!B29,'Rental (BOM)'!$E$106:$E$126)*$E$5 | F29: =SUMIF('Rental (BOM)'!$B$106:$B$126,Pricing!B29,'Rental (BOM)'!$G$106:$G$126)*$F$5 | G29: =SUMIF('Rental (BOM)'!$B$106:$B$126,Pricing!B29,'Rental (BOM)'!$I$106:$I$126)*$G$5 | H29: =SUMIF('Rental (BOM)'!$B$106:$B$126,Pricing!B29,'Rental (BOM)'!$K$106:$K$126)*$H$5 | I29: =SUMIF('Rental (BOM)'!$B$106:$B$126,Pricing!B29,'Rental (BOM)'!$M$106:$M$126)*$I$5
B30: Contract Labor | D30: =SUM(E30,F30,G30,H30,I30) | E30: =SUMIF('Rental (BOM)'!$B$106:$B$126,Pricing!B30,'Rental (BOM)'!$E$106:$E$126)*$E$5 | F30: =SUMIF('Rental (BOM)'!$B$106:$B$126,Pricing!B30,'Rental (BOM)'!$G$106:$G$126)*$F$5 | G30: =SUMIF('Rental (BOM)'!$B$106:$B$126,Pricing!B30,'Rental (BOM)'!$I$106:$I$126)*$G$5 | H30: =SUMIF('Rental (BOM)'!$B$106:$B$126,Pricing!B30,'Rental (BOM)'!$K$106:$K$126)*$H$5 | I30: =SUMIF('Rental (BOM)'!$B$106:$B$126,Pricing!B30,'Rental (BOM)'!$M$106:$M$126)*$I$5
B31: Travel (Air, Uber, Parking, etc) | D31: =SUM(E31,F31,G31,H31,I31) | E31: =SUMIF('Rental (BOM)'!$B$106:$B$126,Pricing!B31,'Rental (BOM)'!$E$106:$E$126)*$E$5 | F31: =SUMIF('Rental (BOM)'!$B$106:$B$126,Pricing!B31,'Rental (BOM)'!$G$106:$G$126)*$F$5 | G31: =SUMIF('Rental (BOM)'!$B$106:$B$126,Pricing!B31,'Rental (BOM)'!$I$106:$I$126)*$G$5 | H31: =SUMIF('Rental (BOM)'!$B$106:$B$126,Pricing!B31,'Rental (BOM)'!$K$106:$K$126)*$H$5 | I31: =SUMIF('Rental (BOM)'!$B$106:$B$126,Pricing!B31,'Rental (BOM)'!$M$106:$M$126)*$I$5
B32: Freight and Shipping | D32: =SUM(E32,F32,G32,H32,I32) | E32: =SUMIF('Rental (BOM)'!$B$106:$B$126,Pricing!B32,'Rental (BOM)'!$E$106:$E$126)*$E$5 | F32: =SUMIF('Rental (BOM)'!$B$106:$B$126,Pricing!B32,'Rental (BOM)'!$G$106:$G$126)*$F$5 | G32: =SUMIF('Rental (BOM)'!$B$106:$B$126,Pricing!B32,'Rental (BOM)'!$I$106:$I$126)*$G$5 | H32: =SUMIF('Rental (BOM)'!$B$106:$B$126,Pricing!B32,'Rental (BOM)'!$K$106:$K$126)*$H$5 | I32: =SUMIF('Rental (BOM)'!$B$106:$B$126,Pricing!B32,'Rental (BOM)'!$M$106:$M$126)*$I$5
B33: Vehicle or Equipment Rental | D33: =SUM(E33,F33,G33,H33,I33) | E33: =SUMIF('Rental (BOM)'!$B$106:$B$126,Pricing!B33,'Rental (BOM)'!$E$106:$E$126)*$E$5 | F33: =SUMIF('Rental (BOM)'!$B$106:$B$126,Pricing!B33,'Rental (BOM)'!$G$106:$G$126)*$F$5 | G33: =SUMIF('Rental (BOM)'!$B$106:$B$126,Pricing!B33,'Rental (BOM)'!$I$106:$I$126)*$G$5 | H33: =SUMIF('Rental (BOM)'!$B$106:$B$126,Pricing!B33,'Rental (BOM)'!$K$106:$K$126)*$H$5 | I33: =SUMIF('Rental (BOM)'!$B$106:$B$126,Pricing!B33,'Rental (BOM)'!$M$106:$M$126)*$I$5
B34: Mileage | D34: =SUM(E34,F34,G34,H34,I34) | E34: =SUMIF('Rental (BOM)'!$B$106:$B$126,Pricing!B34,'Rental (BOM)'!$E$106:$E$126)*$E$5 | F34: =SUMIF('Rental (BOM)'!$B$106:$B$126,Pricing!B34,'Rental (BOM)'!$G$106:$G$126)*$F$5 | G34: =SUMIF('Rental (BOM)'!$B$106:$B$126,Pricing!B34,'Rental (BOM)'!$I$106:$I$126)*$G$5 | H34: =SUMIF('Rental (BOM)'!$B$106:$B$126,Pricing!B34,'Rental (BOM)'!$K$106:$K$126)*$H$5 | I34: =SUMIF('Rental (BOM)'!$B$106:$B$126,Pricing!B34,'Rental (BOM)'!$M$106:$M$126)*$I$5
B35: Hotel & Meals | D35: =SUM(E35,F35,G35,H35,I35) | E35: =SUMIF('Rental (BOM)'!$B$106:$B$126,Pricing!B35,'Rental (BOM)'!$E$106:$E$126)*$E$5 | F35: =SUMIF('Rental (BOM)'!$B$106:$B$126,Pricing!B35,'Rental (BOM)'!$G$106:$G$126)*$F$5 | G35: =SUMIF('Rental (BOM)'!$B$106:$B$126,Pricing!B35,'Rental (BOM)'!$I$106:$I$126)*$G$5 | H35: =SUMIF('Rental (BOM)'!$B$106:$B$126,Pricing!B35,'Rental (BOM)'!$K$106:$K$126)*$H$5 | I35: =SUMIF('Rental (BOM)'!$B$106:$B$126,Pricing!B35,'Rental (BOM)'!$M$106:$M$126)*$I$5
B36: Other | D36: =SUM(E36,F36,G36,H36,I36) | E36: =SUMIF('Rental (BOM)'!$B$106:$B$126,Pricing!B36,'Rental (BOM)'!$E$106:$E$126)*$E$5 | F36: =SUMIF('Rental (BOM)'!$B$106:$B$126,Pricing!B36,'Rental (BOM)'!$G$106:$G$126)*$F$5 | G36: =SUMIF('Rental (BOM)'!$B$106:$B$126,Pricing!B36,'Rental (BOM)'!$I$106:$I$126)*$G$5 | H36: =SUMIF('Rental (BOM)'!$B$106:$B$126,Pricing!B36,'Rental (BOM)'!$K$106:$K$126)*$H$5 | I36: =SUMIF('Rental (BOM)'!$B$106:$B$126,Pricing!B36,'Rental (BOM)'!$M$106:$M$126)*$I$5
B37: -
B38: Recurring Cost | D38: =SUM(D39:D44) | E38: =SUM(E39:E44) | F38: =SUM(F39:F44) | G38: =SUM(G39:G44) | H38: =SUM(H39:H44) | I38: =SUM(I39:I44)
B39: 3rd Party Services | D39: =SUM(E39,F39,G39,H39,I39) | E39: =SUMIF('Rental (BOM)'!$B$128:$B$150,Pricing!B39,'Rental (BOM)'!$E$128:$E$150)*$E$5 | F39: =SUMIF('Rental (BOM)'!$B$128:$B$150,Pricing!B39,'Rental (BOM)'!$G$128:$G$150)*$F$5 | G39: =SUMIF('Rental (BOM)'!$B$128:$B$150,Pricing!B39,'Rental (BOM)'!$I$128:$I$150)*$G$5 | H39: =SUMIF('Rental (BOM)'!$B$128:$B$150,Pricing!B39,'Rental (BOM)'!$K$128:$K$150)*$H$5 | I39: =SUMIF('Rental (BOM)'!$B$128:$B$150,Pricing!B39,'Rental (BOM)'!$M$128:$M$150)*$I$5
B40: Terrestrial Connectivity | D40: =SUM(E40,F40,G40,H40,I40) | E40: =SUMIF('Rental (BOM)'!$B$128:$B$150,Pricing!B40,'Rental (BOM)'!$E$128:$E$150)*$E$5 | F40: =SUMIF('Rental (BOM)'!$B$128:$B$150,Pricing!B40,'Rental (BOM)'!$G$128:$G$150)*$F$5 | G40: =SUMIF('Rental (BOM)'!$B$128:$B$150,Pricing!B40,'Rental (BOM)'!$I$128:$I$150)*$G$5 | H40: =SUMIF('Rental (BOM)'!$B$128:$B$150,Pricing!B40,'Rental (BOM)'!$K$128:$K$150)*$H$5 | I40: =SUMIF('Rental (BOM)'!$B$128:$B$150,Pricing!B40,'Rental (BOM)'!$M$128:$M$150)*$I$5
B41: LEO, MEO, GEO Subscription Recurring | D41: =SUM(E41,F41,G41,H41,I41) | E41: =SUMIF('Rental (BOM)'!$B$128:$B$150,Pricing!B41,'Rental (BOM)'!$E$128:$E$150)*$E$5 | F41: =SUMIF('Rental (BOM)'!$B$128:$B$150,Pricing!B41,'Rental (BOM)'!$G$128:$G$150)*$F$5 | G41: =SUMIF('Rental (BOM)'!$B$128:$B$150,Pricing!B41,'Rental (BOM)'!$I$128:$I$150)*$G$5 | H41: =SUMIF('Rental (BOM)'!$B$128:$B$150,Pricing!B41,'Rental (BOM)'!$K$128:$K$150)*$H$5 | I41: =SUMIF('Rental (BOM)'!$B$128:$B$150,Pricing!B41,'Rental (BOM)'!$M$128:$M$150)*$I$5
B42: Tower Rental | D42: =SUM(E42,F42,G42,H42,I42) | E42: =SUMIF('Rental (BOM)'!$B$128:$B$150,Pricing!B42,'Rental (BOM)'!$E$128:$E$150)*$E$5 | F42: =SUMIF('Rental (BOM)'!$B$128:$B$150,Pricing!B42,'Rental (BOM)'!$G$128:$G$150)*$F$5 | G42: =SUMIF('Rental (BOM)'!$B$128:$B$150,Pricing!B42,'Rental (BOM)'!$I$128:$I$150)*$G$5 | H42: =SUMIF('Rental (BOM)'!$B$128:$B$150,Pricing!B42,'Rental (BOM)'!$K$128:$K$150)*$H$5 | I42: =SUMIF('Rental (BOM)'!$B$128:$B$150,Pricing!B42,'Rental (BOM)'!$M$128:$M$150)*$I$5
...

Sheet Cashflow & Payback
A1: Payback | C1: =Pricing!B1
B2: Summary Column | C2: 0 | D2: =C2+1 | E2: =D2+1 | F2: =E2+1 | G2: =F2+1 | H2: =G2+1 | I2: =H2+1 | J2: =I2+1 | K2: =J2+1 | ... BJ2: =BI2+1
B3: Monthly Gross Profit | D3: =SUM(Pricing!D56)
B6: Flat Rate Install | C6: =SUM('Pricing'!E7:I7)
B7: Initial investment | C7: ='Pricing'!D52-SUM('Pricing'!E7:I7)-'Pricing'!D100
B8: Cash flows | C8: =-C7 | D8: =IF(D$2<='Pricing'!E$4,'Pricing'!E$56,0)+IF(D$2<='Pricing'!F$4,'Pricing'!F$56,0)+IF(D$2<='Pricing'!G$4,'Pricing'!G$56,0)+IF(D$2<='Pricing'!H$4,'Pricing'!H$56,0)+IF(D$2<='Pricing'!I$4,'Pricing'!I$56,0) | E8: =IF(E$2<='Pricing'!E$4,'Pricing'!E$56,0)+IF(E$2<='Pricing'!F$4,'Pricing'!F$56,0)+IF(E$2<='Pricing'!G$4,'Pricing'!G$56,0)+IF(E$2<='Pricing'!H$4,'Pricing'!H$56,0)+IF(E$2<='Pricing'!I$4,'Pricing'!I$56,0) | F8: =IF(F$2<='Pricing'!E$4,'Pricing'!E$56,0)+IF(F$2<='Pricing'!F$4,'Pricing'!F$56,0)+IF(F$2<='Pricing'!G$4,'Pricing'!G$56,0)+IF(F$2<='Pricing'!H$4,'Pricing'!H$56,0)+IF(F$2<='Pricing'!I$4,'Pricing'!I$56,0) | G8: =IF(G$2<='Pricing'!E$4,'Pricing'!E$56,0)+IF(G$2<='Pricing'!F$4,'Pricing'!F$56,0)+IF(G$2<='Pricing'!G$4,'Pricing'!G$56,0)+IF(G$2<='Pricing'!H$4,'Pricing'!H$56,0)+IF(G$2<='Pricing'!I$4,'Pricing'!I$56,0) | H8: =IF(H$2<='Pricing'!E$4,'Pricing'!E$56,0)+IF(H$2<='Pricing'!F$4,'Pricing'!F$56,0)+IF(H$2<='Pricing'!G$4,'Pricing'!G$56,0)+IF(H$2<='Pricing'!H$4,'Pricing'!H$56,0)+IF(H$2<='Pricing'!I$4,'Pricing'!I$56,0) | I8: =IF(I$2<='Pricing'!E$4,'Pricing'!E$56,0)+IF(I$2<='Pricing'!F$4,'Pricing'!F$56,0)+IF(I$2<='Pricing'!G$4,'Pricing'!G$56,0)+IF(I$2<='Pricing'!H$4,'Pricing'!H$56,0)+IF(I$2<='Pricing'!I$4,'Pricing'!I$56,0) | J8: =IF(J$2<='Pricing'!E$4,'Pricing'!E$56,0)+IF(J$2<='Pricing'!F$4,'Pricing'!F$56,0)+IF(J$2<='Pricing'!G$4,'Pricing'!G$56,0)+IF(J$2<='Pricing'!H$4,'Pricing'!H$56,0)+IF(J$2<='Pricing'!I$4,'Pricing'!I$56,0) | K8: =IF(K$2<='Pricing'!E$4,'Pricing'!E$56,0)+IF(K$2<='Pricing'!F$4,'Pricing'!F$56,0)+IF(K$2<='Pricing'!G$4,'Pricing'!G$56,0)+IF(K$2<='Pricing'!H$4,'Pricing'!H$56,0)+IF(K$2<='Pricing'!I$4,'Pricing'!I$56,0) | L8: =IF(L$2<='Pricing'!E$4,'Pricing'!E$56,0)+IF(L$2<='Pricing'!F$4,'Pricing'!F$56,0)+IF(L$2<='Pricing'!G$4,'Pricing'!G$56,0)+IF(L$2<='Pricing'!H$4,'Pricing'!H$56,0)+IF(L$2<='Pricing'!I$4,'Pricing'!I$56,0) | M8: =IF(M$2<='Pricing'!E$4,'Pricing'!E$56,0)+IF(M$2<='Pricing'!F$4,'Pricing'!F$56,0)+IF(M$2<='Pricing'!G$4,'Pricing'!G$56,0)+IF(M$2<='Pricing'!H$4,'Pricing'!H$56,0)+IF(M$2<='Pricing'!I$4,'Pricing'!I$56,0) | N8: =IF(N$2<='Pricing'!E$4,'Pricing'!E$56,0)+IF(N$2<='Pricing'!F$4,'Pricing'!F$56,0)+IF(N$2<='Pricing'!G$4,'Pricing'!G$56,0)+IF(N$2<='Pricing'!H$4,'Pricing'!H$56,0)+IF(N$2<='Pricing'!I$4,'Pricing'!I$56,0) | O8: =IF(O$2<='Pricing'!E$4,'Pricing'!E$56,0)+IF(O$2<='Pricing'!F$4,'Pricing'!F$56,0)+IF(O$2<='Pricing'!G$4,'Pricing'!G$56,0)+IF(O$2<='Pricing'!H$4,'Pricing'!H$56,0)+IF(O$2<='Pricing'!I$4,'Pricing'!I$56,0) | P8: =IF(P$2<='Pricing'!E$4,'Pricing'!E$56,0)+IF(P$2<='Pricing'!F$4,'Pricing'!F$56,0)+IF(P$2<='Pricing'!G$4,'Pricing'!G$56,0)+IF(P$2<='Pricing'!H$4,'Pricing'!H$56,0)+IF(P$2<='Pricing'!I$4,'Pricing'!I$56,0) | Q8: =IF(Q$2<='Pricing'!E$4,'Pricing'!E$56,0)+IF(Q$2<='Pricing'!F$4,'Pricing'!F$56,0)+IF(Q$2<='Pricing'!G$4,'Pricing'!G$56,0)+IF(Q$2<='Pricing'!H$4,'Pricing'!H$56,0)+IF(Q$2<='Pricing'!I$4,'Pricing'!I$56,0) | R8: =IF(R$2<='Pricing'!E$4,'Pricing'!E$56,0)+IF(R$2<='Pricing'!F$4,'Pricing'!F$56,0)+IF(R$2<='Pricing'!G$4,'Pricing'!G$56,0)+IF(R$2<='Pricing'!H$4,'Pricing'!H$56,0)+IF(R$2<='Pricing'!I$4,'Pricing'!I$56,0) | S8: =IF(S$2<='Pricing'!E$4,'Pricing'!E$56,0)+IF(S$2<='Pricing'!F$4,'Pricing'!F$56,0)+IF(S$2<='Pricing'!G$4,'Pricing'!G$56,0)+IF(S$2<='Pricing'!H$4,'Pricing'!H$56,0)+IF(S$2<='Pricing'!I$4,'Pricing'!I$56,0) | T8: =IF(T$2<='Pricing'!E$4,'Pricing'!E$56,0)+IF(T$2<='Pricing'!F$4,'Pricing'!F$56,0)+IF(T$2<='Pricing'!G$4,'Pricing'!G$56,0)+IF(T$2<='Pricing'!H$4,'Pricing'!H$56,0)+IF(T$2<='Pricing'!I$4,'Pricing'!I$56,0) | U8: =IF(U$2<='Pricing'!E$4,'Pricing'!E$56,0)+IF(U$2<='Pricing'!F$4,'Pricing'!F$56,0)+IF(U$2<='Pricing'!G$4,'Pricing'!G$56,0)+IF(U$2<='Pricing'!H$4,'Pricing'!H$56,0)+IF(U$2<='Pricing'!I$4,'Pricing'!I$56,0) | V8: =IF(V$2<='Pricing'!E$4,'Pricing'!E$56,0)+IF(V$2<='Pricing'!F$4,'Pricing'!F$56,0)+IF(V$2<='Pricing'!G$4,'Pricing'!G$56,0)+IF(V$2<='Pricing'!H$4,'Pricing'!H$56,0)+IF(V$2<='Pricing'!I$4,'Pricing'!I$56,0) | W8: =IF(W$2<='Pricing'!E$4,'Pricing'!E$56,0)+IF(W$2<='Pricing'!F$4,'Pricing'!F$56,0)+IF(W$2<='Pricing'!G$4,'Pricing'!G$56,0)+IF(W$2<='Pricing'!H$4,'Pricing'!H$56,0)+IF(W$2<='Pricing'!I$4,'Pricing'!I$56,0) | X8: =IF(X$2<='Pricing'!E$4,'Pricing'!E$56,0)+IF(X$2<='Pricing'!F$4,'Pricing'!F$56,0)+IF(X$2<='Pricing'!G$4,'Pricing'!G$56,0)+IF(X$2<='Pricing'!H$4,'Pricing'!H$56,0)+IF(X$2<='Pricing'!I$4,'Pricing'!I$56,0) | Y8: =IF(Y$2<='Pricing'!E$4,'Pricing'!E$56,0)+IF(Y$2<='Pricing'!F$4,'Pricing'!F$56,0)+IF(Y$2<='Pricing'!G$4,'Pricing'!G$56,0)+IF(Y$2<='Pricing'!H$4,'Pricing'!H$56,0)+IF(Y$2<='Pricing'!I$4,'Pricing'!I$56,0) | Z8: =IF(Z$2<='Pricing'!E$4,'Pricing'!E$56,0)+IF(Z$2<='Pricing'!F$4,'Pricing'!F$56,0)+IF(Z$2<='Pricing'!G$4,'Pricing'!G$56,0)+IF(Z$2<='Pricing'!H$4,'Pricing'!H$56,0)+IF(Z$2<='Pricing'!I$4,'Pricing'!I$56,0) | AA8: =IF(AA$2<='Pricing'!E$4,'Pricing'!E$56,0)+IF(AA$2<='Pricing'!F$4,'Pricing'!F$56,0)+IF(AA$2<='Pricing'!G$4,'Pricing'!G$56,0)+IF(AA$2<='Pricing'!H$4,'Pricing'!H$56,0)+IF(AA$2<='Pricing'!I$4,'Pricing'!I$56,0) | AB8: =IF(AB$2<='Pricing'!E$4,'Pricing'!E$56,0)+IF(AB$2<='Pricing'!F$4,'Pricing'!F$56,0)+IF(AB$2<='Pricing'!G$4,'Pricing'!G$56,0)+IF(AB$2<='Pricing'!H$4,'Pricing'!H$56,0)+IF(AB$2<='Pricing'!I$4,'Pricing'!I$56,0) | AC8: =IF(AC$2<='Pricing'!E$4,'Pricing'!E$56,0)+IF(AC$2<='Pricing'!F$4,'Pricing'!F$56,0)+IF(AC$2<='Pricing'!G$4,'Pricing'!G$56,0)+IF(AC$2<='Pricing'!H$4,'Pricing'!H$56,0)+IF(AC$2<='Pricing'!I$4,'Pricing'!I$56,0) | AD8: =IF(AD$2<='Pricing'!E$4,'Pricing'!E$56,0)+IF(AD$2<='Pricing'!F$4,'Pricing'!F$56,0)+IF(AD$2<='Pricing'!G$4,'Pricing'!G$56,0)+IF(AD$2<='Pricing'!H$4,'Pricing'!H$56,0)+IF(AD$2<='Pricing'!I$4,'Pricing'!I$56,0) | AE8: =IF(AE$2<='Pricing'!E$4,'Pricing'!E$56,0)+IF(AE$2<='Pricing'!F$4,'Pricing'!F$56,0)+IF(AE$2<='Pricing'!G$4,'Pricing'!G$56,0)+IF(AE$2<='Pricing'!H$4,'Pricing'!H$56,0)+IF(AE$2<='Pricing'!I$4,'Pricing'!I$56,0) | AF8: =IF(AF$2<='Pricing'!E$4,'Pricing'!E$56,0)+IF(AF$2<='Pricing'!F$4,'Pricing'!F$56,0)+IF(AF$2<='Pricing'!G$4,'Pricing'!G$56,0)+IF(AF$2<='Pricing'!H$4,'Pricing'!H$56,0)+IF(AF$2<='Pricing'!I$4,'Pricing'!I$56,0) | AG8: =IF(AG$2<='Pricing'!E$4,'Pricing'!E$56,0)+IF(AG$2<='Pricing'!F$4,'Pricing'!F$56,0)+IF(AG$2<='Pricing'!G$4,'Pricing'!G$56,0)+IF(AG$2<='Pricing'!H$4,'Pricing'!H$56,0)+IF(AG$2<='Pricing'!I$4,'Pricing'!I$56,0) | AH8: =IF(AH$2<='Pricing'!E$4,'Pricing'!E$56,0)+IF(AH$2<='Pricing'!F$4,'Pricing'!F$56,0)+IF(AH$2<='Pricing'!G$4,'Pricing'!G$56,0)+IF(AH$2<='Pricing'!H$4,'Pricing'!H$56,0)+IF(AH$2<='Pricing'!I$4,'Pricing'!I$56,0) | AI8: =IF(AI$2<='Pricing'!E$4,'Pricing'!E$56,0)+IF(AI$2<='Pricing'!F$4,'Pricing'!F$56,0)+IF(AI$2<='Pricing'!G$4,'Pricing'!G$56,0)+IF(AI$2<='Pricing'!H$4,'Pricing'!H$56,0)+IF(AI$2<='Pricing'!I$4,'Pricing'!I$56,0) | AJ8: =IF(AJ$2<='Pricing'!E$4,'Pricing'!E$56,0)+IF(AJ$2<='Pricing'!F$4,'Pricing'!F$56,0)+IF(AJ$2<='Pricing'!G$4,'Pricing'!G$56,0)+IF(AJ$2<='Pricing'!H$4,'Pricing'!H$56,0)+IF(AJ$2<='Pricing'!I$4,'Pricing'!I$56,0) | AK8: =IF(AK$2<='Pricing'!E$4,'Pricing'!E$56,0)+IF(AK$2<='Pricing'!F$4,'Pricing'!F$56,0)+IF(AK$2<='Pricing'!G$4,'Pricing'!G$56,0)+IF(AK$2<='Pricing'!H$4,'Pricing'!H$56,0)+IF(AK$2<='Pricing'!I$4,'Pricing'!I$56,0) | AL8: =IF(AL$2<='Pricing'!E$4,'Pricing'!E$56,0)+IF(AL$2<='Pricing'!F$4,'Pricing'!F$56,0)+IF(AL$2<='Pricing'!G$4,'Pricing'!G$56,0)+IF(AL$2<='Pricing'!H$4,'Pricing'!H$56,0)+IF(AL$2<='Pricing'!I$4,'Pricing'!I$56,0) | AM8: =IF(AM$2<='Pricing'!E$4,'Pricing'!E$56,0)+IF(AM$2<='Pricing'!F$4,'Pricing'!F$56,0)+IF(AM$2<='Pricing'!G$4,'Pricing'!G$56,0)+IF(AM$2<='Pricing'!H$4,'Pricing'!H$56,0)+IF(AM$2<='Pricing'!I$4,'Pricing'!I$56,0) | AN8: =IF(AN$2<='Pricing'!E$4,'Pricing'!E$56,0)+IF(AN$2<='Pricing'!F$4,'Pricing'!F$56,0)+IF(AN$2<='Pricing'!G$4,'Pricing'!G$56,0)+IF(AN$2<='Pricing'!H$4,'Pricing'!H$56,0)+IF(AN$2<='Pricing'!I$4,'Pricing'!I$56,0) | AO8: =IF(AO$2<='Pricing'!E$4,'Pricing'!E$56,0)+IF(AO$2<='Pricing'!F$4,'Pricing'!F$56,0)+IF(AO$2<='Pricing'!G$4,'Pricing'!G$56,0)+IF(AO$2<='Pricing'!H$4,'Pricing'!H$56,0)+IF(AO$2<='Pricing'!I$4,'Pricing'!I$56,0) | AP8: =IF(AP$2<='Pricing'!E$4,'Pricing'!E$56,0)+IF(AP$2<='Pricing'!F$4,'Pricing'!F$56,0)+IF(AP$2<='Pricing'!G$4,'Pricing'!G$56,0)+IF(AP$2<='Pricing'!H$4,'Pricing'!H$56,0)+IF(AP$2<='Pricing'!I$4,'Pricing'!I$56,0) | AQ8: =IF(AQ$2<='Pricing'!E$4,'Pricing'!E$56,0)+IF(AQ$2<='Pricing'!F$4,'Pricing'!F$56,0)+IF(AQ$2<='Pricing'!G$4,'Pricing'!G$56,0)+IF(AQ$2<='Pricing'!H$4,'Pricing'!H$56,0)+IF(AQ$2<='Pricing'!I$4,'Pricing'!I$56,0) | AR8: =IF(AR$2<='Pricing'!E$4,'Pricing'!E$56,0)+IF(AR$2<='Pricing'!F$4,'Pricing'!F$56,0)+IF(AR$2<='Pricing'!G$4,'Pricing'!G$56,0)+IF(AR$2<='Pricing'!H$4,'Pricing'!H$56,0)+IF(AR$2<='Pricing'!I$4,'Pricing'!I$56,0) | AS8: =IF(AS$2<='Pricing'!E$4,'Pricing'!E$56,0)+IF(AS$2<='Pricing'!F$4,'Pricing'!F$56,0)+IF(AS$2<='Pricing'!G$4,'Pricing'!G$56,0)+IF(AS$2<='Pricing'!H$4,'Pricing'!H$56,0)+IF(AS$2<='Pricing'!I$4,'Pricing'!I$56,0) | AT8: =IF(AT$2<='Pricing'!E$4,'Pricing'!E$56,0)+IF(AT$2<='Pricing'!F$4,'Pricing'!F$56,0)+IF(AT$2<='Pricing'!G$4,'Pricing'!G$56,0)+IF(AT$2<='Pricing'!H$4,'Pricing'!H$56,0)+IF(AT$2<='Pricing'!I$4,'Pricing'!I$56,0) | AU8: =IF(AU$2<='Pricing'!E$4,'Pricing'!E$56,0)+IF(AU$2<='Pricing'!F$4,'Pricing'!F$56,0)+IF(AU$2<='Pricing'!G$4,'Pricing'!G$56,0)+IF(AU$2<='Pricing'!H$4,'Pricing'!H$56,0)+IF(AU$2<='Pricing'!I$4,'Pricing'!I$56,0) | AV8: =IF(AV$2<='Pricing'!E$4,'Pricing'!E$56,0)+IF(AV$2<='Pricing'!F$4,'Pricing'!F$56,0)+IF(AV$2<='Pricing'!G$4,'Pricing'!G$56,0)+IF(AV$2<='Pricing'!H$4,'Pricing'!H$56,0)+IF(AV$2<='Pricing'!I$4,'Pricing'!I$56,0) | AW8: =IF(AW$2<='Pricing'!E$4,'Pricing'!E$56,0)+IF(AW$2<='Pricing'!F$4,'Pricing'!F$56,0)+IF(AW$2<='Pricing'!G$4,'Pricing'!G$56,0)+IF(AW$2<='Pricing'!H$4,'Pricing'!H$56,0)+IF(AW$2<='Pricing'!I$4,'Pricing'!I$56,0) | AX8: =IF(AX$2<='Pricing'!E$4,'Pricing'!E$56,0)+IF(AX$2<='Pricing'!F$4,'Pricing'!F$56,0)+IF(AX$2<='Pricing'!G$4,'Pricing'!G$56,0)+IF(AX$2<='Pricing'!H$4,'Pricing'!H$56,0)+IF(AX$2<='Pricing'!I$4,'Pricing'!I$56,0) | AY8: =IF(AY$2<='Pricing'!E$4,'Pricing'!E$56,0)+IF(AY$2<='Pricing'!F$4,'Pricing'!F$56,0)+IF(AY$2<='Pricing'!G$4,'Pricing'!G$56,0)+IF(AY$2<='Pricing'!H$4,'Pricing'!H$56,0)+IF(AY$2<='Pricing'!I$4,'Pricing'!I$56,0) | AZ8: =IF(AZ$2<='Pricing'!E$4,'Pricing'!E$56,0)+IF(AZ$2<='Pricing'!F$4,'Pricing'!F$56,0)+IF(AZ$2<='Pricing'!G$4,'Pricing'!G$56,0)+IF(AZ$2<='Pricing'!H$4,'Pricing'!H$56,0)+IF(AZ$2<='Pricing'!I$4,'Pricing'!I$56,0) | BA8: =IF(BA$2<='Pricing'!E$4,'Pricing'!E$56,0)+IF(BA$2<='Pricing'!F$4,'Pricing'!F$56,0)+IF(BA$2<='Pricing'!G$4,'Pricing'!G$56,0)+IF(BA$2<='Pricing'!H$4,'Pricing'!H$56,0)+IF(BA$2<='Pricing'!I$4,'Pricing'!I$56,0) | BB8: =IF(BB$2<='Pricing'!E$4,'Pricing'!E$56,0)+IF(BB$2<='Pricing'!F$4,'Pricing'!F$56,0)+IF(BB$2<='Pricing'!G$4,'Pricing'!G$56,0)+IF(BB$2<='Pricing'!H$4,'Pricing'!H$56,0)+IF(BB$2<='Pricing'!I$4,'Pricing'!I$56,0) | BC8: =IF(BC$2<='Pricing'!E$4,'Pricing'!E$56,0)+IF(BC$2<='Pricing'!F$4,'Pricing'!F$56,0)+IF(BC$2<='Pricing'!G$4,'Pricing'!G$56,0)+IF(BC$2<='Pricing'!H$4,'Pricing'!H$56,0)+IF(BC$2<='Pricing'!I$4,'Pricing'!I$56,0) | BD8: =IF(BD$2<='Pricing'!E$4,'Pricing'!E$56,0)+IF(BD$2<='Pricing'!F$4,'Pricing'!F$56,0)+IF(BD$2<='Pricing'!G$4,'Pricing'!G$56,0)+IF(BD$2<='Pricing'!H$4,'Pricing'!H$56,0)+IF(BD$2<='Pricing'!I$4,'Pricing'!I$56,0) | BE8: =IF(BE$2<='Pricing'!E$4,'Pricing'!E$56,0)+IF(BE$2<='Pricing'!F$4,'Pricing'!F$56,0)+IF(BE$2<='Pricing'!G$4,'Pricing'!G$56,0)+IF(BE$2<='Pricing'!H$4,'Pricing'!H$56,0)+IF(BE$2<='Pricing'!I$4,'Pricing'!I$56,0) | BF8: =IF(BF$2<='Pricing'!E$4,'Pricing'!E$56,0)+IF(BF$2<='Pricing'!F$4,'Pricing'!F$56,0)+IF(BF$2<='Pricing'!G$4,'Pricing'!G$56,0)+IF(BF$2<='Pricing'!H$4,'Pricing'!H$56,0)+IF(BF$2<='Pricing'!I$4,'Pricing'!I$56,0) | BG8: =IF(BG$2<='Pricing'!E$4,'Pricing'!E$56,0)+IF(BG$2<='Pricing'!F$4,'Pricing'!F$56,0)+IF(BG$2<='Pricing'!G$4,'Pricing'!G$56,0)+IF(BG$2<='Pricing'!H$4,'Pricing'!H$56,0)+IF(BG$2<='Pricing'!I$4,'Pricing'!I$56,0) | BH8: =IF(BH$2<='Pricing'!E$4,'Pricing'!E$56,0)+IF(BH$2<='Pricing'!F$4,'Pricing'!F$56,0)+IF(BH$2<='Pricing'!G$4,'Pricing'!G$56,0)+IF(BH$2<='Pricing'!H$4,'Pricing'!H$56,0)+IF(BH$2<='Pricing'!I$4,'Pricing'!I$56,0) | BI8: =IF(BI$2<='Pricing'!E$4,'Pricing'!E$56,0)+IF(BI$2<='Pricing'!F$4,'Pricing'!F$56,0)+IF(BI$2<='Pricing'!G$4,'Pricing'!G$56,0)+IF(BI$2<='Pricing'!H$4,'Pricing'!H$56,0)+IF(BI$2<='Pricing'!I$4,'Pricing'!I$56,0) | BJ8: =IF(BJ$2<='Pricing'!E$4,'Pricing'!E$56,0)+IF(BJ$2<='Pricing'!F$4,'Pricing'!F$56,0)+IF(BJ$2<='Pricing'!G$4,'Pricing'!G$56,0)+IF(BJ$2<='Pricing'!H$4,'Pricing'!H$56,0)+IF(BJ$2<='Pricing'!I$4,'Pricing'!I$56,0)
B10: Cumulative cash flows | C10: =C8 | D10: =SUM($C8:D8) | E10: =SUM($C8:E8) | F10: =SUM($C8:F8) | G10: =SUM($C8:G8) | H10: =SUM($C8:H8) | I10: =SUM($C8:I8) | J10: =SUM($C8:J8) | K10: =SUM($C8:K8) | ... BJ10: =SUM($C8:BJ8)
D11: =IF(AND(C10<0,D10>=0,D8>0),-C10/D8,"n/m") | E11: =IF(AND(D10<0,E10>=0,E8>0),-D10/E8,"n/m") | F11: =IF(AND(E10<0,F10>=0,F8>0),-E10/F8,"n/m") | G11: =IF(AND(F10<0,G10>=0,G8>0),-F10/G8,"n/m") | H11: =IF(AND(G10<0,H10>=0,H8>0),-G10/H8,"n/m") | I11: =IF(AND(H10<0,I10>=0,I8>0),-H10/I8,"n/m") | J11: =IF(AND(I10<0,J10>=0,J8>0),-I10/J8,"n/m") | K11: =IF(AND(J10<0,K10>=0,K8>0),-J10/K8,"n/m") | ... BJ11: =IF(AND(BI10<0,BJ10>=0,BJ8>0),-BI10/BJ8,"n/m")
B14: Payback period | C14: =IF(C7<=0,0,IF(BJ10<0,"n/m",COUNTIF(D10:BJ10,"<0")+INDEX(D11:BJ11,1,COUNTIF(D10:BJ10,"<0")+1)))
B17: Breaking it down >
B18: The Integer | C18: =IF(ISNUMBER(C14),INT(C14),"n/m")
B19: The Fraction | C19: =IF(ISNUMBER(C14),MOD(C14,1),"n/m")
B22: Bonus: Payback period calculations in just one cell
B23: Payback period | C23: =C14
B27: Column 1 | C27: 0 | D27: =C27+1 | E27: =D27+1 | F27: =E27+1 | G27: =F27+1 | H27: =G27+1 | I27: =H27+1 | J27: =I27+1 | K27: =J27+1 | ... BJ27: =BI27+1
B28: Monthly Gross Profit | D28: =SUM(Pricing!E56)
B32: Initial investment | C32: ='Pricing'!E52-'Pricing'!E7-'Pricing'!E100
B33: Cash flows | C33: =-C32 | D33: =IF(D$27<='Pricing'!E$4,'Pricing'!E$56,0) | E33: =IF(E$27<='Pricing'!E$4,'Pricing'!E$56,0) | F33: =IF(F$27<='Pricing'!E$4,'Pricing'!E$56,0) | G33: =IF(G$27<='Pricing'!E$4,'Pricing'!E$56,0) | H33: =IF(H$27<='Pricing'!E$4,'Pricing'!E$56,0) | I33: =IF(I$27<='Pricing'!E$4,'Pricing'!E$56,0) | J33: =IF(J$27<='Pricing'!E$4,'Pricing'!E$56,0) | K33: =IF(K$27<='Pricing'!E$4,'Pricing'!E$56,0) | L33: =IF(L$27<='Pricing'!E$4,'Pricing'!E$56,0) | M33: =IF(M$27<='Pricing'!E$4,'Pricing'!E$56,0) | N33: =IF(N$27<='Pricing'!E$4,'Pricing'!E$56,0) | O33: =IF(O$27<='Pricing'!E$4,'Pricing'!E$56,0) | P33: =IF(P$27<='Pricing'!E$4,'Pricing'!E$56,0) | Q33: =IF(Q$27<='Pricing'!E$4,'Pricing'!E$56,0) | R33: =IF(R$27<='Pricing'!E$4,'Pricing'!E$56,0) | S33: =IF(S$27<='Pricing'!E$4,'Pricing'!E$56,0) | T33: =IF(T$27<='Pricing'!E$4,'Pricing'!E$56,0) | U33: =IF(U$27<='Pricing'!E$4,'Pricing'!E$56,0) | V33: =IF(V$27<='Pricing'!E$4,'Pricing'!E$56,0) | W33: =IF(W$27<='Pricing'!E$4,'Pricing'!E$56,0) | X33: =IF(X$27<='Pricing'!E$4,'Pricing'!E$56,0) | Y33: =IF(Y$27<='Pricing'!E$4,'Pricing'!E$56,0) | Z33: =IF(Z$27<='Pricing'!E$4,'Pricing'!E$56,0) | AA33: =IF(AA$27<='Pricing'!E$4,'Pricing'!E$56,0) | AB33: =IF(AB$27<='Pricing'!E$4,'Pricing'!E$56,0) | AC33: =IF(AC$27<='Pricing'!E$4,'Pricing'!E$56,0) | AD33: =IF(AD$27<='Pricing'!E$4,'Pricing'!E$56,0) | AE33: =IF(AE$27<='Pricing'!E$4,'Pricing'!E$56,0) | AF33: =IF(AF$27<='Pricing'!E$4,'Pricing'!E$56,0) | AG33: =IF(AG$27<='Pricing'!E$4,'Pricing'!E$56,0) | AH33: =IF(AH$27<='Pricing'!E$4,'Pricing'!E$56,0) | AI33: =IF(AI$27<='Pricing'!E$4,'Pricing'!E$56,0) | AJ33: =IF(AJ$27<='Pricing'!E$4,'Pricing'!E$56,0) | AK33: =IF(AK$27<='Pricing'!E$4,'Pricing'!E$56,0) | AL33: =IF(AL$27<='Pricing'!E$4,'Pricing'!E$56,0) | AM33: =IF(AM$27<='Pricing'!E$4,'Pricing'!E$56,0) | AN33: =IF(AN$27<='Pricing'!E$4,'Pricing'!E$56,0) | AO33: =IF(AO$27<='Pricing'!E$4,'Pricing'!E$56,0) | AP33: =IF(AP$27<='Pricing'!E$4,'Pricing'!E$56,0) | AQ33: =IF(AQ$27<='Pricing'!E$4,'Pricing'!E$56,0) | AR33: =IF(AR$27<='Pricing'!E$4,'Pricing'!E$56,0) | AS33: =IF(AS$27<='Pricing'!E$4,'Pricing'!E$56,0) | AT33: =IF(AT$27<='Pricing'!E$4,'Pricing'!E$56,0) | AU33: =IF(AU$27<='Pricing'!E$4,'Pricing'!E$56,0) | AV33: =IF(AV$27<='Pricing'!E$4,'Pricing'!E$56,0) | AW33: =IF(AW$27<='Pricing'!E$4,'Pricing'!E$56,0) | AX33: =IF(AX$27<='Pricing'!E$4,'Pricing'!E$56,0) | AY33: =IF(AY$27<='Pricing'!E$4,'Pricing'!E$56,0) | AZ33: =IF(AZ$27<='Pricing'!E$4,'Pricing'!E$56,0) | BA33: =IF(BA$27<='Pricing'!E$4,'Pricing'!E$56,0) | BB33: =IF(BB$27<='Pricing'!E$4,'Pricing'!E$56,0) | BC33: =IF(BC$27<='Pricing'!E$4,'Pricing'!E$56,0) | BD33: =IF(BD$27<='Pricing'!E$4,'Pricing'!E$56,0) | BE33: =IF(BE$27<='Pricing'!E$4,'Pricing'!E$56,0) | BF33: =IF(BF$27<='Pricing'!E$4,'Pricing'!E$56,0) | BG33: =IF(BG$27<='Pricing'!E$4,'Pricing'!E$56,0) | BH33: =IF(BH$27<='Pricing'!E$4,'Pricing'!E$56,0) | BI33: =IF(BI$27<='Pricing'!E$4,'Pricing'!E$56,0) | BJ33: =IF(BJ$27<='Pricing'!E$4,'Pricing'!E$56,0)
B35: Cumulative cash flows | C35: =C33 | D35: =SUM($C33:D33) | E35: =SUM($C33:E33) | F35: =SUM($C33:F33) | G35: =SUM($C33:G33) | H35: =SUM($C33:H33) | I35: =SUM($C33:I33) | J35: =SUM($C33:J33) | K35: =SUM($C33:K33) | ... BJ35: =SUM($C33:BJ33)
D36: =IF(AND(C35<0,D35>=0,D33>0),-C35/D33,"n/m") | E36: =IF(AND(D35<0,E35>=0,E33>0),-D35/E33,"n/m") | F36: =IF(AND(E35<0,F35>=0,F33>0),-E35/F33,"n/m") | G36: =IF(AND(F35<0,G35>=0,G33>0),-F35/G33,"n/m") | H36: =IF(AND(G35<0,H35>=0,H33>0),-G35/H33,"n/m") | I36: =IF(AND(H35<0,I35>=0,I33>0),-H35/I33,"n/m") | J36: =IF(AND(I35<0,J35>=0,J33>0),-I35/J33,"n/m") | K36: =IF(AND(J35<0,K35>=0,K33>0),-J35/K33,"n/m") | ... BJ36: =IF(AND(BI35<0,BJ35>=0,BJ33>0),-BI35/BJ33,"n/m")
B39: Payback period | C39: =IF(C32<=0,0,IF(AND('Pricing'!E56>0,C32<='Pricing'!E56*'Pricing'!E4),C32/'Pricing'!E56,"n/m"))
B42: Breaking it down >
B43: The Integer | C43: =IF(ISNUMBER(C39),INT(C39),"n/m")
B44: The Fraction | C44: =IF(ISNUMBER(C39),MOD(C39,1),"n/m")
B47: Bonus: Payback period calculations in just one cell
B48: Payback period | C48: =C39
B53: Column 2 | C53: 0 | D53: =C53+1 | E53: =D53+1 | F53: =E53+1 | G53: =F53+1 | H53: =G53+1 | I53: =H53+1 | J53: =I53+1 | K53: =J53+1 | ... BJ53: =BI53+1
B54: Monthly Gross Profit | D54: =SUM(Pricing!F56)
B58: Initial investment | C58: ='Pricing'!F52-'Pricing'!F7-'Pricing'!F100
B59: Cash flows | C59: =-C58 | D59: =IF(D$53<='Pricing'!F$4,'Pricing'!F$56,0) | E59: =IF(E$53<='Pricing'!F$4,'Pricing'!F$56,0) | F59: =IF(F$53<='Pricing'!F$4,'Pricing'!F$56,0) | G59: =IF(G$53<='Pricing'!F$4,'Pricing'!F$56,0) | H59: =IF(H$53<='Pricing'!F$4,'Pricing'!F$56,0) | I59: =IF(I$53<='Pricing'!F$4,'Pricing'!F$56,0) | J59: =IF(J$53<='Pricing'!F$4,'Pricing'!F$56,0) | K59: =IF(K$53<='Pricing'!F$4,'Pricing'!F$56,0) | L59: =IF(L$53<='Pricing'!F$4,'Pricing'!F$56,0) | M59: =IF(M$53<='Pricing'!F$4,'Pricing'!F$56,0) | N59: =IF(N$53<='Pricing'!F$4,'Pricing'!F$56,0) | O59: =IF(O$53<='Pricing'!F$4,'Pricing'!F$56,0) | P59: =IF(P$53<='Pricing'!F$4,'Pricing'!F$56,0) | Q59: =IF(Q$53<='Pricing'!F$4,'Pricing'!F$56,0) | R59: =IF(R$53<='Pricing'!F$4,'Pricing'!F$56,0) | S59: =IF(S$53<='Pricing'!F$4,'Pricing'!F$56,0) | T59: =IF(T$53<='Pricing'!F$4,'Pricing'!F$56,0) | U59: =IF(U$53<='Pricing'!F$4,'Pricing'!F$56,0) | V59: =IF(V$53<='Pricing'!F$4,'Pricing'!F$56,0) | W59: =IF(W$53<='Pricing'!F$4,'Pricing'!F$56,0) | X59: =IF(X$53<='Pricing'!F$4,'Pricing'!F$56,0) | Y59: =IF(Y$53<='Pricing'!F$4,'Pricing'!F$56,0) | Z59: =IF(Z$53<='Pricing'!F$4,'Pricing'!F$56,0) | AA59: =IF(AA$53<='Pricing'!F$4,'Pricing'!F$56,0) | AB59: =IF(AB$53<='Pricing'!F$4,'Pricing'!F$56,0) | AC59: =IF(AC$53<='Pricing'!F$4,'Pricing'!F$56,0) | AD59: =IF(AD$53<='Pricing'!F$4,'Pricing'!F$56,0) | AE59: =IF(AE$53<='Pricing'!F$4,'Pricing'!F$56,0) | AF59: =IF(AF$53<='Pricing'!F$4,'Pricing'!F$56,0) | AG59: =IF(AG$53<='Pricing'!F$4,'Pricing'!F$56,0) | AH59: =IF(AH$53<='Pricing'!F$4,'Pricing'!F$56,0) | AI59: =IF(AI$53<='Pricing'!F$4,'Pricing'!F$56,0) | AJ59: =IF(AJ$53<='Pricing'!F$4,'Pricing'!F$56,0) | AK59: =IF(AK$53<='Pricing'!F$4,'Pricing'!F$56,0) | AL59: =IF(AL$53<='Pricing'!F$4,'Pricing'!F$56,0) | AM59: =IF(AM$53<='Pricing'!F$4,'Pricing'!F$56,0) | AN59: =IF(AN$53<='Pricing'!F$4,'Pricing'!F$56,0) | AO59: =IF(AO$53<='Pricing'!F$4,'Pricing'!F$56,0) | AP59: =IF(AP$53<='Pricing'!F$4,'Pricing'!F$56,0) | AQ59: =IF(AQ$53<='Pricing'!F$4,'Pricing'!F$56,0) | AR59: =IF(AR$53<='Pricing'!F$4,'Pricing'!F$56,0) | AS59: =IF(AS$53<='Pricing'!F$4,'Pricing'!F$56,0) | AT59: =IF(AT$53<='Pricing'!F$4,'Pricing'!F$56,0) | AU59: =IF(AU$53<='Pricing'!F$4,'Pricing'!F$56,0) | AV59: =IF(AV$53<='Pricing'!F$4,'Pricing'!F$56,0) | AW59: =IF(AW$53<='Pricing'!F$4,'Pricing'!F$56,0) | AX59: =IF(AX$53<='Pricing'!F$4,'Pricing'!F$56,0) | AY59: =IF(AY$53<='Pricing'!F$4,'Pricing'!F$56,0) | AZ59: =IF(AZ$53<='Pricing'!F$4,'Pricing'!F$56,0) | BA59: =IF(BA$53<='Pricing'!F$4,'Pricing'!F$56,0) | BB59: =IF(BB$53<='Pricing'!F$4,'Pricing'!F$56,0) | BC59: =IF(BC$53<='Pricing'!F$4,'Pricing'!F$56,0) | BD59: =IF(BD$53<='Pricing'!F$4,'Pricing'!F$56,0) | BE59: =IF(BE$53<='Pricing'!F$4,'Pricing'!F$56,0) | BF59: =IF(BF$53<='Pricing'!F$4,'Pricing'!F$56,0) | BG59: =IF(BG$53<='Pricing'!F$4,'Pricing'!F$56,0) | BH59: =IF(BH$53<='Pricing'!F$4,'Pricing'!F$56,0) | BI59: =IF(BI$53<='Pricing'!F$4,'Pricing'!F$56,0) | BJ59: =IF(BJ$53<='Pricing'!F$4,'Pricing'!F$56,0)
B61: Cumulative cash flows | C61: =C59 | D61: =SUM($C59:D59) | E61: =SUM($C59:E59) | F61: =SUM($C59:F59) | G61: =SUM($C59:G59) | H61: =SUM($C59:H59) | I61: =SUM($C59:I59) | J61: =SUM($C59:J59) | K61: =SUM($C59:K59) | ... BJ61: =SUM($C59:BJ59)
D62: =IF(AND(C61<0,D61>=0,D59>0),-C61/D59,"n/m") | E62: =IF(AND(D61<0,E61>=0,E59>0),-D61/E59,"n/m") | F62: =IF(AND(E61<0,F61>=0,F59>0),-E61/F59,"n/m") | G62: =IF(AND(F61<0,G61>=0,G59>0),-F61/G59,"n/m") | H62: =IF(AND(G61<0,H61>=0,H59>0),-G61/H59,"n/m") | I62: =IF(AND(H61<0,I61>=0,I59>0),-H61/I59,"n/m") | J62: =IF(AND(I61<0,J61>=0,J59>0),-I61/J59,"n/m") | K62: =IF(AND(J61<0,K61>=0,K59>0),-J61/K59,"n/m") | ... BJ62: =IF(AND(BI61<0,BJ61>=0,BJ59>0),-BI61/BJ59,"n/m")
B65: Payback period | C65: =IF(C58<=0,0,IF(AND('Pricing'!F56>0,C58<='Pricing'!F56*'Pricing'!F4),C58/'Pricing'!F56,"n/m"))
B68: Breaking it down >
B69: The Integer | C69: =IF(ISNUMBER(C65),INT(C65),"n/m")
B70: The Fraction | C70: =IF(ISNUMBER(C65),MOD(C65,1),"n/m")
B73: Bonus: Payback period calculations in just one cell
B74: Payback period | C74: =C65
B79: Column 3 | C79: 0 | D79: =C79+1 | E79: =D79+1 | F79: =E79+1 | G79: =F79+1 | H79: =G79+1 | I79: =H79+1 | J79: =I79+1 | K79: =J79+1 | ... BJ79: =BI79+1
B80: Monthly Gross Profit | D80: =SUM(Pricing!G56)
...

Sheet Exec Summary
B1: =Pricing!B1
B2: Business Case
B4: Date:
B5: Customer:
B6: Account Manager:
B7: Solution Engineer:
B8: Project Name:
B9: Project Description
B18: Financial Summary
B19: Rental | F19: Option 1 | H19: Option 2 | J19: Option 3 | L19: Option 4 | N19: Option 5
B20: Option Description | D20: → | F20: ='Pricing'!E3 | G20: 0 | H20: ='Pricing'!F3 | J20: ='Pricing'!G3 | L20: ='Pricing'!H3 | N20: ='Pricing'!I3
B21: Term (Months) | D21: → | F21: ='Pricing'!E4 | G21: =SUM(Pricing!F4) | H21: ='Pricing'!F4 | I21: =SUM(Pricing!H4) | J21: ='Pricing'!G4 | K21: =SUM(Pricing!J4) | L21: ='Pricing'!H4 | M21: =SUM(Pricing!L4) | N21: ='Pricing'!I4
B22: Number of Sites/Units | D22: → | F22: ='Pricing'!E5 | G22: =SUM(Pricing!F5) | H22: ='Pricing'!F5 | I22: =SUM(Pricing!H5) | J22: ='Pricing'!G5 | K22: =SUM(Pricing!J5) | L22: ='Pricing'!H5 | M22: =SUM(Pricing!L5) | N22: ='Pricing'!I5
B23: Costs | D23: Summary
B24: Capex | D24: ='Pricing'!D52 | F24: ='Pricing'!E52 | H24: ='Pricing'!F52 | J24: ='Pricing'!G52 | L24: ='Pricing'!H52 | N24: ='Pricing'!I52
B25: Labor | D25: ='Pricing'!D24 | F25: ='Pricing'!E24 | H25: ='Pricing'!F24 | J25: ='Pricing'!G24 | L25: ='Pricing'!H24 | N25: ='Pricing'!I24
B26: Operating Costs (Monthly) | D26: ='Pricing'!D53 | F26: ='Pricing'!E53 | H26: ='Pricing'!F53 | J26: ='Pricing'!G53 | L26: ='Pricing'!H53 | N26: ='Pricing'!I53
B27: Revenue
B28: Monthly Rate | D28: ='Pricing'!D55 | F28: ='Pricing'!E55 | H28: ='Pricing'!F55 | J28: ='Pricing'!G55 | L28: ='Pricing'!H55 | N28: ='Pricing'!I55
B29: Flat Rate Installation | D29: =SUM('Pricing'!E7:I7) | F29: ='Pricing'!E7 | H29: ='Pricing'!F7 | I29: =SUM(Pricing!G7) | J29: ='Pricing'!G7 | K29: =SUM(Pricing!I7) | L29: ='Pricing'!H7 | N29: ='Pricing'!I7
B30: TCV | D30: ='Pricing'!D54 | F30: ='Pricing'!E54 | H30: ='Pricing'!F54 | I30: =Pricing!G54 | J30: ='Pricing'!G54 | L30: ='Pricing'!H54 | N30: ='Pricing'!I54
B31: Monthly Gross Profit | D31: ='Pricing'!D56 | F31: ='Pricing'!E56 | H31: ='Pricing'!F56 | J31: ='Pricing'!G56 | L31: ='Pricing'!H56 | N31: ='Pricing'!I56
B32: Monthly Contribution Margin | D32: ='Pricing'!D57 | F32: ='Pricing'!E57 | H32: ='Pricing'!F57 | J32: ='Pricing'!G57 | L32: ='Pricing'!H57 | N32: ='Pricing'!I57
B33: NPV | D33: ='Pricing'!D58 | E33: =SUM(Pricing!D58) | F33: ='Pricing'!E58 | G33: =Pricing!F58 | H33: ='Pricing'!F58 | I33: =Pricing!H58 | J33: ='Pricing'!G58 | K33: =Pricing!J58 | L33: ='Pricing'!H58 | M33: =Pricing!L58 | N33: ='Pricing'!I58
B34: IRR | D34: ='Pricing'!D59 | E34: =SUM(Pricing!D59) | F34: ='Pricing'!E59 | G34: =Pricing!F59 | H34: ='Pricing'!F59 | I34: =Pricing!H59 | J34: ='Pricing'!G59 | K34: =Pricing!J59 | L34: ='Pricing'!H59 | M34: =Pricing!L59 | N34: ='Pricing'!I59
B35: Payback Period in Months | D35: ='Pricing'!D60 | F35: ='Pricing'!E60 | H35: ='Pricing'!F60 | J35: ='Pricing'!G60 | L35: ='Pricing'!H60 | N35: ='Pricing'!I60
B36: Cash Flow | D36: ='Pricing'!D61 | F36: ='Pricing'!E61 | H36: ='Pricing'!F61 | J36: ='Pricing'!G61 | L36: ='Pricing'!H61 | N36: ='Pricing'!I61
B38: Purchase | F38: Option 1 | H38: Option 2 | J38: Option 3 | L38: Option 4 | N38: Option 5
B39: Option Description | D39: → | F39: ='Pricing'!E64 | G39: ='Rental (BOM)'!E4 | H39: ='Pricing'!F64 | I39: ='Rental (BOM)'!G4 | J39: ='Pricing'!G64 | K39: ='Rental (BOM)'!I4 | L39: ='Pricing'!H64 | M39: ='Rental (BOM)'!K4 | N39: ='Pricing'!I64
B40: Number Packages (Same Configuration) | D40: → | F40: ='Pricing'!E65 | G40: =Pricing!F65 | H40: ='Pricing'!F65 | I40: =Pricing!H65 | J40: ='Pricing'!G65 | K40: =Pricing!J65 | L40: ='Pricing'!H65 | M40: =Pricing!L65 | N40: ='Pricing'!I65
D41: Summary
B42: Hardware Cost | D42: ='Pricing'!D97 | F42: ='Pricing'!E97 | H42: ='Pricing'!F97 | J42: ='Pricing'!G97 | L42: ='Pricing'!H97 | N42: ='Pricing'!I97
B43: Labor Cost | D43: ='Pricing'!D98 | F43: ='Pricing'!E98 | H43: ='Pricing'!F98 | J43: ='Pricing'!G98 | L43: ='Pricing'!H98 | N43: ='Pricing'!I98
B44: Sale Price | D44: ='Pricing'!D99 | F44: ='Pricing'!E99 | H44: ='Pricing'!F99 | J44: ='Pricing'!G99 | L44: ='Pricing'!H99 | N44: ='Pricing'!I99
B45: Deal Gross Profit | D45: ='Pricing'!D100 | F45: ='Pricing'!E100 | H45: ='Pricing'!F100 | J45: ='Pricing'!G100 | L45: ='Pricing'!H100 | N45: ='Pricing'!I100
B46: Contribution Margin | D46: ='Pricing'!D101 | F46: ='Pricing'!E101 | H46: ='Pricing'!F101 | J46: ='Pricing'!G101 | L46: ='Pricing'!H101 | N46: ='Pricing'!I101
B49: Approval Signatures
B51: CEO: | L51: Date:
B53: CFO: | L53: Date:
B55: Region GM and/or Area GM: | L55: Date:
...

Sheet NPV - IRR
A1: =Pricing!B1
B3: WACC | C3: 0.15 | D3: Cost of Capital
D5: COLUMN 1
C6: YEAR | D6: CAPEX | E6: Cash Flow | G6: Cumulative Cash Flow | I6: IRR | J6: =IFERROR(IRR(E7:E17),"n/m") | L6: Footnotes
B7: Year | C7: 0 | D7: ='Pricing'!E52-'Pricing'!E7-'Pricing'!E100 | E7: =-D7 | G7: =SUM(E$7:E7) | I7: NPV | J7: =NPV($C$3,E8:E17)+E7 | L7: Cash Flow is Calculated from Gross Margin Dollars
B8: Year | C8: 1 | E8: ='Pricing'!E$56*MAX(0,MIN(12,'Pricing'!E$4-(C8-1)*12)) | G8: =SUM(E$7:E8) | I8: Payback Month | J8: ='Pricing'!E60
